Workbook

Sheet README
A1: 매트리스 BOM(Bill of Materials, 자재명세서) 관리 템플릿 — 사용 안내
B2: 이 파일은 상품별 부품 구성·제조사·담당자·개발 진행률을 한 곳에서 관리하기 위한 템플릿입니다. 추후 관계형 DB(Database)와 내부 툴로 이전하는 것을 전제로, '시트 = 테이블, 코드 = 기본키' 구조로 설계되어 있습니다.
A4: 1. 용어 풀이
A5: 약자 | B5: 풀텍스트 | F5: 쉬운 말
A6: BOM | B6: Bill of Materials (자재명세서) | F6: 구성표. '이 상품 하나를 만들려면 어떤 부품이 몇 개 들어가나'
A7: AVL | B7: Approved Vendor List (승인 협력사 목록) | F7: '이 부품은 어느 업체에서 사도 되나, 사내에서 누가 챙기나'
A8: NPI | B8: New Product Introduction (신제품 개발 진행관리) | F8: '지금 어디까지 왔고, 무엇이 막혀 있나'
A9: EVT | B9: Engineering Validation Test (설계 검증) | F9: 개발 1단계. 일단 동작하는지 확인하는 시제품 단계
A10: DVT | B10: Design Validation Test (디자인/품질 검증) | F10: 개발 2단계. 설계대로 품질·내구성이 나오는지 시험
A11: PVT | B11: Production Validation Test (양산 검증) | F11: 개발 3단계. 실제 공장·양산 조건으로 소량 생산해 문제 확인
A12: MP | B12: Mass Production (양산) | F12: 개발 완료, 본격 생산
A13: ECN | B13: Engineering Change Notice (설계변경 통지) | F13: '무엇을, 왜, 언제 바꿨나'의 기록. 사양·제조사·SW 버전 변경 포함
A14: Rev. | B14: Revision (리비전) | F14: 같은 부품의 버전. 사양이 바뀌면 A→B로 올림
A15: PM | B15: Product Manager (상품 담당자) | F15: 상품 하나의 개발 일정·구성 전체를 책임지는 사람
A16: PK / FK | B16: Primary Key / Foreign Key (기본키 / 외래키) | F16: DB 용어. PK=행을 구분하는 고유 코드, FK=다른 표의 코드를 참조하는 열
A17: IoT | B17: Internet of Things (사물인터넷) | F17: 컨트롤러를 앱·서버와 연결하는 통신 모듈(IoT Stick)
A19: 2. 시트 구조
A20: 그룹 | B20: 시트 | F20: 설명
A21: 마스터 | B21: 상품마스터 / 품목마스터 / 협력사마스터 / 담당자마스터 | F21: 각 코드가 PK(Primary Key, 기본키). 이름·속성은 여기서만 정의하고 다른 시트는 코드로 참조합니다.
A22: 관계 | B22: BOM(Bill of Materials) / AVL(Approved Vendor List) | F22: 상품↔부품 구성, 부품↔협력사↔사내담당자 매핑. 코드만 입력하면 이름은 수식으로 자동 표시됩니다.
A23: 현황 | B23: NPI(New Product Introduction)진행현황 / 상품별완성률 | F23: 부품별 단계·완료율·이슈 입력 → 상품별완성률은 자동 집계(입력 없음).
A24: 이력 | B24: ECN(Engineering Change Notice)변경이력 | F24: 사양·제조사·SW 버전 변경 기록. 승인 시 품목마스터의 리비전도 함께 올립니다.
A25: 참조 | B25: 코드표 | F25: 드롭다운 목록. 값을 추가하려면 해당 열 아래에 이어서 입력합니다.
A26: 셀 색상 범례
A27: 연노랑 | B27: 직접 입력하는 셀
A28: 연파랑 | B28: PK(기본키) 코드 셀 — 반드시 마스터에 먼저 등록된 코드를 사용
A29: 회색 | B29: 수식 셀 — 수정 금지. '※미등록'이 표시되면 해당 코드가 마스터에 없다는 뜻
A30: 품번 체계
A31: CV-### | B31: 커버 (000=어셈블리, 001~=커버, 010~=폼, 020~=라벨)
A32: CT-### | B32: 컨트롤러 (000=어셈블리, 001=본체 아세이, 002~=부속품)
A33: PK-### | B33: 포장 (000=어셈블리, 001~003=포장방식 사양, 010~=포장재) ※ 여기서 PK는 Packaging의 약자입니다
A34: SW-### | B34: APP/서버 (버전은 리비전 열에 기록, 리전은 별도 품번)
A35: 규칙 | B35: 같은 부품이면 상품이 달라도 같은 품번. 사양이 바뀌면 Rev.(리비전) 업 + ECN 기록. 완전히 다른 부품이면 새 품번 발급.
A37: 3. 시트별 용도와 역할 (입력자 / 관리자 / 조회자)
B38: 역할은 세 가지로 나눕니다. 입력자 = 데이터를 넣는 사람, 관리자(오너) = 구조와 코드 체계를 지키게 하는 책임자, 조회자 = 보기만 하는 사람. 작은 조직에서는 한 사람이 여러 역할을 겸해도 됩니다. 이 표는 나중에 내부 툴을 만들 때 그대로 권한(역할) 설계가 됩니다.
A39: 시트 | B39: 한 줄 용도 | E39: 입력자 | H39: 관리자(오너) | K39: 주요 조회자
A40: 상품마스터 | B40: 우리가 만드는 상품 목록 | E40: 상품기획 / PM | H40: PM | K40: 전원
A41: 품목마스터 | B41: 모든 부품의 사전. 품번·사양·리비전 | E41: 각 부품 담당 개발자 | H41: 품번 관리자 1명 (개발팀장 또는 구매) | K41: 전원
A42: BOM | B42: 상품별로 어떤 부품이 몇 개 들어가는지 | E42: 상품 담당 개발자 / PM | H42: PM | K42: 구매, 생산, 품질
A43: 협력사마스터 | B43: 거래 제조사 목록·연락처 | E43: 구매 | H43: 구매 | K43: 개발, 품질
...

Sheet 상품마스터
A1: 상품코드 | B1: 상품명 | C1: 상품군 | D1: 상태 | E1: 출시목표일 | F1: PM(담당자ID) | G1: PM 이름 | H1: 커버 분리수 | I1: 비고
A2: MAT-001 | B2: 에어매트리스 A (커버 2분리) | C2: 에어매트리스 | D2: 개발 | E2: 2026-12-01 | F2: E-001 | G2: =IF(F2="","",IFERROR(INDEX(담당자마스터!$B$2:$B$300,MATCH(F2,담당자마스터!$A$2:$A$300,0)),"※미등록")) -> 김OO | H2: 2 | I2: 예시 데이터
A3: MAT-002 | B3: 에어매트리스 B (커버 3분리) | C3: 에어매트리스 | D3: 기획 | E3: 2027-03-01 | F3: E-001 | G3: =IF(F3="","",IFERROR(INDEX(담당자마스터!$B$2:$B$300,MATCH(F3,담당자마스터!$A$2:$A$300,0)),"※미등록")) -> 김OO | H3: 3 | I3: 예시 데이터 (BOM 미작성)
G4: =IF(F4="","",IFERROR(INDEX(담당자마스터!$B$2:$B$300,MATCH(F4,담당자마스터!$A$2:$A$300,0)),"※미등록"))
G5: =IF(F5="","",IFERROR(INDEX(담당자마스터!$B$2:$B$300,MATCH(F5,담당자마스터!$A$2:$A$300,0)),"※미등록"))
G6: =IF(F6="","",IFERROR(INDEX(담당자마스터!$B$2:$B$300,MATCH(F6,담당자마스터!$A$2:$A$300,0)),"※미등록"))
G7: =IF(F7="","",IFERROR(INDEX(담당자마스터!$B$2:$B$300,MATCH(F7,담당자마스터!$A$2:$A$300,0)),"※미등록"))
G8: =IF(F8="","",IFERROR(INDEX(담당자마스터!$B$2:$B$300,MATCH(F8,담당자마스터!$A$2:$A$300,0)),"※미등록"))
G9: =IF(F9="","",IFERROR(INDEX(담당자마스터!$B$2:$B$300,MATCH(F9,담당자마스터!$A$2:$A$300,0)),"※미등록"))
G10: =IF(F10="","",IFERROR(INDEX(담당자마스터!$B$2:$B$300,MATCH(F10,담당자마스터!$A$2:$A$300,0)),"※미등록"))
G11: =IF(F11="","",IFERROR(INDEX(담당자마스터!$B$2:$B$300,MATCH(F11,담당자마스터!$A$2:$A$300,0)),"※미등록"))
G12: =IF(F12="","",IFERROR(INDEX(담당자마스터!$B$2:$B$300,MATCH(F12,담당자마스터!$A$2:$A$300,0)),"※미등록"))
G13: =IF(F13="","",IFERROR(INDEX(담당자마스터!$B$2:$B$300,MATCH(F13,담당자마스터!$A$2:$A$300,0)),"※미등록"))
G14: =IF(F14="","",IFERROR(INDEX(담당자마스터!$B$2:$B$300,MATCH(F14,담당자마스터!$A$2:$A$300,0)),"※미등록"))
G15: =IF(F15="","",IFERROR(INDEX(담당자마스터!$B$2:$B$300,MATCH(F15,담당자마스터!$A$2:$A$300,0)),"※미등록"))
... G300: =IF(F300="","",IFERROR(INDEX(담당자마스터!$B$2:$B$300,MATCH(F300,담당자마스터!$A$2:$A$300,0)),"※미등록"))

Sheet 품목마스터
A1: 품번 | B1: 품명 | C1: 대분류 | D1: 중분류 | E1: 품목구분 | F1: 규격/사양 | G1: 단위 | H1: 리비전 | I1: 사양서/도면 링크 | J1: 특징/메모 | K1: 등록일
A2: CV-000 | B2: 커버 어셈블리 | C2: 커버 | D2: 어셈블리 | E2: 어셈블리 | F2: 커버1~3 + 폼 + 라벨 조립품 | G2: SET | H2: A | J2: 제품별 커버 분리 수 상이(2~3)
A3: CV-001 | B3: 커버1 (상판) | C3: 커버 | D3: 커버 | E3: 부품 | F3: 예: 니트 원단, 규격 입력 | G3: EA | H3: A
A4: CV-002 | B4: 커버2 (하판) | C4: 커버 | D4: 커버 | E4: 부품 | G4: EA | H4: A
A5: CV-003 | B5: 커버3 (측면) | C5: 커버 | D5: 커버 | E5: 부품 | G5: EA | H5: A | J5: 3분리 제품에만 사용
A6: CV-010 | B6: 폼 | C6: 커버 | D6: 폼 | E6: 부품 | F6: 예: 밀도/두께 입력 | G6: EA | H6: A
A7: CV-020 | B7: 로우라벨 (법정표시) | C7: 커버 | D7: 라벨 | E7: 부품 | G7: EA | H7: A | J7: KC/세탁표시 등
A8: CV-021 | B8: 로고라벨 | C8: 커버 | D8: 라벨 | E8: 부품 | G8: EA | H8: A
A9: CT-000 | B9: 컨트롤러 어셈블리 | C9: 컨트롤러 | D9: 어셈블리 | E9: 어셈블리 | F9: 컨트롤러 본체 + 부속품 세트 | G9: SET | H9: A
A10: CT-001 | B10: 컨트롤러 아세이 (윈도우커버라벨 포함) | C10: 컨트롤러 | D10: 본체 | E10: 부품 | F10: 아세이 버전은 리비전으로 관리 | G10: EA | H10: A | J10: 윈도우커버라벨 사양 변경 시 리비전 업
A11: CT-002 | B11: 어댑터 | C11: 컨트롤러 | D11: 전원 | E11: 부품 | F11: 예: 12V 2A | G11: EA | H11: A | J11: 인증(KC) 여부 확인
A12: CT-003 | B12: 에어호스 | C12: 컨트롤러 | D12: 배관 | E12: 부품 | F12: 예: 길이/내경 | G12: EA | H12: A
A13: CT-004 | B13: 매뉴얼 | C13: 컨트롤러 | D13: 문서 | E13: 문서 | G13: EA | H13: A | J13: 언어/버전 관리
A14: CT-005 | B14: IoT Stick | C14: 컨트롤러 | D14: 통신 | E14: 부품 | F14: 예: Wi-Fi/BLE | G14: EA | H14: A | J14: FW 버전은 ECN으로 추적
A15: CT-006 | B15: 컨트롤러 포장박스 | C15: 컨트롤러 | D15: 포장재 | E15: 포장재 | G15: EA | H15: A
A16: PK-000 | B16: 완제품 포장 어셈블리 | C16: 포장 | D16: 어셈블리 | E16: 어셈블리 | F16: 포장방식 + 박스 + 비닐 | G16: SET | H16: A
A17: PK-001 | B17: 포장방식 A | C17: 포장 | D17: 포장사양 | E17: 포장사양 | F17: 예: 롤팩(압축) | G17: - | H17: A | J17: 포장 방식은 사양 품목으로 관리
A18: PK-002 | B18: 포장방식 B | C18: 포장 | D18: 포장사양 | E18: 포장사양 | F18: 예: 평판 박스 | G18: - | H18: A
A19: PK-003 | B19: 포장방식 C | C19: 포장 | D19: 포장사양 | E19: 포장사양 | G19: - | H19: A
A20: PK-010 | B20: 완제품 포장박스 | C20: 포장 | D20: 박스 | E20: 포장재 | F20: 예: 외경 규격 | G20: EA | H20: A
A21: PK-011 | B21: 포장비닐 | C21: 포장 | D21: 비닐 | E21: 포장재 | G21: EA | H21: A
A22: SW-000 | B22: APP/서버 세트 | C22: APP | D22: 어셈블리 | E22: 어셈블리 | F22: 앱 + 서버 구성 | G22: SET | H22: A
A23: SW-001 | B23: Android 앱 | C23: APP | D23: 모바일앱 | E23: 소프트웨어 | F23: 버전은 리비전에 기록 | G23: - | H23: 1.0.0
A24: SW-002 | B24: iOS 앱 | C24: APP | D24: 모바일앱 | E24: 소프트웨어 | G24: - | H24: 1.0.0
A25: SW-003 | B25: 서버 - KR 리전 | C25: APP | D25: 서버 | E25: 소프트웨어 | G25: - | H25: 1.0.0
A26: SW-004 | B26: 서버 - US 리전 | C26: APP | D26: 서버 | E26: 소프트웨어 | G26: - | H26: 1.0.0 | J26: 해외 출시 시 사용

Sheet BOM
A1: 상품코드 | B1: 레벨 | C1: 상위품번 | D1: 품번 | E1: 품명 | F1: 소요량 | G1: 단위 | H1: 필수여부 | I1: 대체품번 | J1: 비고
A2: MAT-001 | B2: 1 | D2: CV-000 | E2: =IF(D2="","",IFERROR(INDEX(품목마스터!$B$2:$B$300,MATCH(D2,품목마스터!$A$2:$A$300,0)),"※미등록")) -> 커버 어셈블리 | F2: 1 | G2: =IF(D2="","",IFERROR(INDEX(품목마스터!$G$2:$G$300,MATCH(D2,품목마스터!$A$2:$A$300,0)),"※미등록")) -> SET | H2: 필수 | J2: 레벨1 = 완제품 직속
A3: MAT-001 | B3: 2 | C3: CV-000 | D3: CV-001 | E3: =IF(D3="","",IFERROR(INDEX(품목마스터!$B$2:$B$300,MATCH(D3,품목마스터!$A$2:$A$300,0)),"※미등록")) -> 커버1 (상판) | F3: 1 | G3: =IF(D3="","",IFERROR(INDEX(품목마스터!$G$2:$G$300,MATCH(D3,품목마스터!$A$2:$A$300,0)),"※미등록")) -> EA | H3: 필수
A4: MAT-001 | B4: 2 | C4: CV-000 | D4: CV-002 | E4: =IF(D4="","",IFERROR(INDEX(품목마스터!$B$2:$B$300,MATCH(D4,품목마스터!$A$2:$A$300,0)),"※미등록")) -> 커버2 (하판) | F4: 1 | G4: =IF(D4="","",IFERROR(INDEX(품목마스터!$G$2:$G$300,MATCH(D4,품목마스터!$A$2:$A$300,0)),"※미등록")) -> EA | H4: 필수
A5: MAT-001 | B5: 2 | C5: CV-000 | D5: CV-010 | E5: =IF(D5="","",IFERROR(INDEX(품목마스터!$B$2:$B$300,MATCH(D5,품목마스터!$A$2:$A$300,0)),"※미등록")) -> 폼 | F5: 1 | G5: =IF(D5="","",IFERROR(INDEX(품목마스터!$G$2:$G$300,MATCH(D5,품목마스터!$A$2:$A$300,0)),"※미등록")) -> EA | H5: 필수
A6: MAT-001 | B6: 2 | C6: CV-000 | D6: CV-020 | E6: =IF(D6="","",IFERROR(INDEX(품목마스터!$B$2:$B$300,MATCH(D6,품목마스터!$A$2:$A$300,0)),"※미등록")) -> 로우라벨 (법정표시) | F6: 1 | G6: =IF(D6="","",IFERROR(INDEX(품목마스터!$G$2:$G$300,MATCH(D6,품목마스터!$A$2:$A$300,0)),"※미등록")) -> EA | H6: 필수
A7: MAT-001 | B7: 2 | C7: CV-000 | D7: CV-021 | E7: =IF(D7="","",IFERROR(INDEX(품목마스터!$B$2:$B$300,MATCH(D7,품목마스터!$A$2:$A$300,0)),"※미등록")) -> 로고라벨 | F7: 1 | G7: =IF(D7="","",IFERROR(INDEX(품목마스터!$G$2:$G$300,MATCH(D7,품목마스터!$A$2:$A$300,0)),"※미등록")) -> EA | H7: 필수
A8: MAT-001 | B8: 1 | D8: CT-000 | E8: =IF(D8="","",IFERROR(INDEX(품목마스터!$B$2:$B$300,MATCH(D8,품목마스터!$A$2:$A$300,0)),"※미등록")) -> 컨트롤러 어셈블리 | F8: 1 | G8: =IF(D8="","",IFERROR(INDEX(품목마스터!$G$2:$G$300,MATCH(D8,품목마스터!$A$2:$A$300,0)),"※미등록")) -> SET | H8: 필수
A9: MAT-001 | B9: 2 | C9: CT-000 | D9: CT-001 | E9: =IF(D9="","",IFERROR(INDEX(품목마스터!$B$2:$B$300,MATCH(D9,품목마스터!$A$2:$A$300,0)),"※미등록")) -> 컨트롤러 아세이 (윈도우커버라벨 포함) | F9: 1 | G9: =IF(D9="","",IFERROR(INDEX(품목마스터!$G$2:$G$300,MATCH(D9,품목마스터!$A$2:$A$300,0)),"※미등록")) -> EA | H9: 필수
A10: MAT-001 | B10: 2 | C10: CT-000 | D10: CT-002 | E10: =IF(D10="","",IFERROR(INDEX(품목마스터!$B$2:$B$300,MATCH(D10,품목마스터!$A$2:$A$300,0)),"※미등록")) -> 어댑터 | F10: 1 | G10: =IF(D10="","",IFERROR(INDEX(품목마스터!$G$2:$G$300,MATCH(D10,품목마스터!$A$2:$A$300,0)),"※미등록")) -> EA | H10: 필수
A11: MAT-001 | B11: 2 | C11: CT-000 | D11: CT-003 | E11: =IF(D11="","",IFERROR(INDEX(품목마스터!$B$2:$B$300,MATCH(D11,품목마스터!$A$2:$A$300,0)),"※미등록")) -> 에어호스 | F11: 2 | G11: =IF(D11="","",IFERROR(INDEX(품목마스터!$G$2:$G$300,MATCH(D11,품목마스터!$A$2:$A$300,0)),"※미등록")) -> EA | H11: 필수 | J11: 좌/우 2개
A12: MAT-001 | B12: 2 | C12: CT-000 | D12: CT-004 | E12: =IF(D12="","",IFERROR(INDEX(품목마스터!$B$2:$B$300,MATCH(D12,품목마스터!$A$2:$A$300,0)),"※미등록")) -> 매뉴얼 | F12: 1 | G12: =IF(D12="","",IFERROR(INDEX(품목마스터!$G$2:$G$300,MATCH(D12,품목마스터!$A$2:$A$300,0)),"※미등록")) -> EA | H12: 필수
A13: MAT-001 | B13: 2 | C13: CT-000 | D13: CT-005 | E13: =IF(D13="","",IFERROR(INDEX(품목마스터!$B$2:$B$300,MATCH(D13,품목마스터!$A$2:$A$300,0)),"※미등록")) -> IoT Stick | F13: 1 | G13: =IF(D13="","",IFERROR(INDEX(품목마스터!$G$2:$G$300,MATCH(D13,품목마스터!$A$2:$A$300,0)),"※미등록")) -> EA | H13: 옵션 | J13: IoT 모델만
A14: MAT-001 | B14: 2 | C14: CT-000 | D14: CT-006 | E14: =IF(D14="","",IFERROR(INDEX(품목마스터!$B$2:$B$300,MATCH(D14,품목마스터!$A$2:$A$300,0)),"※미등록")) -> 컨트롤러 포장박스 | F14: 1 | G14: =IF(D14="","",IFERROR(INDEX(품목마스터!$G$2:$G$300,MATCH(D14,품목마스터!$A$2:$A$300,0)),"※미등록")) -> EA | H14: 필수
A15: MAT-001 | B15: 1 | D15: PK-000 | E15: =IF(D15="","",IFERROR(INDEX(품목마스터!$B$2:$B$300,MATCH(D15,품목마스터!$A$2:$A$300,0)),"※미등록")) -> 완제품 포장 어셈블리 | F15: 1 | G15: =IF(D15="","",IFERROR(INDEX(품목마스터!$G$2:$G$300,MATCH(D15,품목마스터!$A$2:$A$300,0)),"※미등록")) -> SET | H15: 필수
A16: MAT-001 | B16: 2 | C16: PK-000 | D16: PK-001 | E16: =IF(D16="","",IFERROR(INDEX(품목마스터!$B$2:$B$300,MATCH(D16,품목마스터!$A$2:$A$300,0)),"※미등록")) -> 포장방식 A | F16: 1 | G16: =IF(D16="","",IFERROR(INDEX(품목마스터!$G$2:$G$300,MATCH(D16,품목마스터!$A$2:$A$300,0)),"※미등록")) -> - | H16: 필수 | I16: PK-002 | J16: 포장방식 A 기본, B 대체 가능
A17: MAT-001 | B17: 2 | C17: PK-000 | D17: PK-010 | E17: =IF(D17="","",IFERROR(INDEX(품목마스터!$B$2:$B$300,MATCH(D17,품목마스터!$A$2:$A$300,0)),"※미등록")) -> 완제품 포장박스 | F17: 1 | G17: =IF(D17="","",IFERROR(INDEX(품목마스터!$G$2:$G$300,MATCH(D17,품목마스터!$A$2:$A$300,0)),"※미등록")) -> EA | H17: 필수
A18: MAT-001 | B18: 2 | C18: PK-000 | D18: PK-011 | E18: =IF(D18="","",IFERROR(INDEX(품목마스터!$B$2:$B$300,MATCH(D18,품목마스터!$A$2:$A$300,0)),"※미등록")) -> 포장비닐 | F18: 1 | G18: =IF(D18="","",IFERROR(INDEX(품목마스터!$G$2:$G$300,MATCH(D18,품목마스터!$A$2:$A$300,0)),"※미등록")) -> EA | H18: 필수
A19: MAT-001 | B19: 1 | D19: SW-000 | E19: =IF(D19="","",IFERROR(INDEX(품목마스터!$B$2:$B$300,MATCH(D19,품목마스터!$A$2:$A$300,0)),"※미등록")) -> APP/서버 세트 | F19: 1 | G19: =IF(D19="","",IFERROR(INDEX(품목마스터!$G$2:$G$300,MATCH(D19,품목마스터!$A$2:$A$300,0)),"※미등록")) -> SET | H19: 필수
A20: MAT-001 | B20: 2 | C20: SW-000 | D20: SW-001 | E20: =IF(D20="","",IFERROR(INDEX(품목마스터!$B$2:$B$300,MATCH(D20,품목마스터!$A$2:$A$300,0)),"※미등록")) -> Android 앱 | F20: 1 | G20: =IF(D20="","",IFERROR(INDEX(품목마스터!$G$2:$G$300,MATCH(D20,품목마스터!$A$2:$A$300,0)),"※미등록")) -> - | H20: 필수
A21: MAT-001 | B21: 2 | C21: SW-000 | D21: SW-002 | E21: =IF(D21="","",IFERROR(INDEX(품목마스터!$B$2:$B$300,MATCH(D21,품목마스터!$A$2:$A$300,0)),"※미등록")) -> iOS 앱 | F21: 1 | G21: =IF(D21="","",IFERROR(INDEX(품목마스터!$G$2:$G$300,MATCH(D21,품목마스터!$A$2:$A$300,0)),"※미등록")) -> - | H21: 필수
A22: MAT-001 | B22: 2 | C22: SW-000 | D22: SW-003 | E22: =IF(D22="","",IFERROR(INDEX(품목마스터!$B$2:$B$300,MATCH(D22,품목마스터!$A$2:$A$300,0)),"※미등록")) -> 서버 - KR 리전 | F22: 1 | G22: =IF(D22="","",IFERROR(INDEX(품목마스터!$G$2:$G$300,MATCH(D22,품목마스터!$A$2:$A$300,0)),"※미등록")) -> - | H22: 필수 | J22: KR 리전
E23: =IF(D23="","",IFERROR(INDEX(품목마스터!$B$2:$B$300,MATCH(D23,품목마스터!$A$2:$A$300,0)),"※미등록")) | G23: =IF(D23="","",IFERROR(INDEX(품목마스터!$G$2:$G$300,MATCH(D23,품목마스터!$A$2:$A$300,0)),"※미등록"))
E24: =IF(D24="","",IFERROR(INDEX(품목마스터!$B$2:$B$300,MATCH(D24,품목마스터!$A$2:$A$300,0)),"※미등록")) | G24: =IF(D24="","",IFERROR(INDEX(품목마스터!$G$2:$G$300,MATCH(D24,품목마스터!$A$2:$A$300,0)),"※미등록"))
E25: =IF(D25="","",IFERROR(INDEX(품목마스터!$B$2:$B$300,MATCH(D25,품목마스터!$A$2:$A$300,0)),"※미등록")) | G25: =IF(D25="","",IFERROR(INDEX(품목마스터!$G$2:$G$300,MATCH(D25,품목마스터!$A$2:$A$300,0)),"※미등록"))
E26: =IF(D26="","",IFERROR(INDEX(품목마스터!$B$2:$B$300,MATCH(D26,품목마스터!$A$2:$A$300,0)),"※미등록")) | G26: =IF(D26="","",IFERROR(INDEX(품목마스터!$G$2:$G$300,MATCH(D26,품목마스터!$A$2:$A$300,0)),"※미등록"))
E27: =IF(D27="","",IFERROR(INDEX(품목마스터!$B$2:$B$300,MATCH(D27,품목마스터!$A$2:$A$300,0)),"※미등록")) | G27: =IF(D27="","",IFERROR(INDEX(품목마스터!$G$2:$G$300,MATCH(D27,품목마스터!$A$2:$A$300,0)),"※미등록"))
E28: =IF(D28="","",IFERROR(INDEX(품목마스터!$B$2:$B$300,MATCH(D28,품목마스터!$A$2:$A$300,0)),"※미등록")) | G28: =IF(D28="","",IFERROR(INDEX(품목마스터!$G$2:$G$300,MATCH(D28,품목마스터!$A$2:$A$300,0)),"※미등록"))
E29: =IF(D29="","",IFERROR(INDEX(품목마스터!$B$2:$B$300,MATCH(D29,품목마스터!$A$2:$A$300,0)),"※미등록")) | G29: =IF(D29="","",IFERROR(INDEX(품목마스터!$G$2:$G$300,MATCH(D29,품목마스터!$A$2:$A$300,0)),"※미등록"))
E30: =IF(D30="","",IFERROR(INDEX(품목마스터!$B$2:$B$300,MATCH(D30,품목마스터!$A$2:$A$300,0)),"※미등록")) | G30: =IF(D30="","",IFERROR(INDEX(품목마스터!$G$2:$G$300,MATCH(D30,품목마스터!$A$2:$A$300,0)),"※미등록"))
E31: =IF(D31="","",IFERROR(INDEX(품목마스터!$B$2:$B$300,MATCH(D31,품목마스터!$A$2:$A$300,0)),"※미등록")) | G31: =IF(D31="","",IFERROR(INDEX(품목마스터!$G$2:$G$300,MATCH(D31,품목마스터!$A$2:$A$300,0)),"※미등록"))
E32: =IF(D32="","",IFERROR(INDEX(품목마스터!$B$2:$B$300,MATCH(D32,품목마스터!$A$2:$A$300,0)),"※미등록")) | G32: =IF(D32="","",IFERROR(INDEX(품목마스터!$G$2:$G$300,MATCH(D32,품목마스터!$A$2:$A$300,0)),"※미등록"))
E33: =IF(D33="","",IFERROR(INDEX(품목마스터!$B$2:$B$300,MATCH(D33,품목마스터!$A$2:$A$300,0)),"※미등록")) | G33: =IF(D33="","",IFERROR(INDEX(품목마스터!$G$2:$G$300,MATCH(D33,품목마스터!$A$2:$A$300,0)),"※미등록"))
E34: =IF(D34="","",IFERROR(INDEX(품목마스터!$B$2:$B$300,MATCH(D34,품목마스터!$A$2:$A$300,0)),"※미등록")) | G34: =IF(D34="","",IFERROR(INDEX(품목마스터!$G$2:$G$300,MATCH(D34,품목마스터!$A$2:$A$300,0)),"※미등록"))
... E300: =IF(D300="","",IFERROR(INDEX(품목마스터!$B$2:$B$300,MATCH(D300,품목마스터!$A$2:$A$300,0)),"※미등록")) | G300: =IF(D300="","",IFERROR(INDEX(품목마스터!$G$2:$G$300,MATCH(D300,품목마스터!$A$2:$A$300,0)),"※미등록"))

Sheet 협력사마스터
A1: 협력사코드 | B1: 협력사명 | C1: 유형 | D1: 국가 | E1: 담당자명 | F1: 연락처 | G1: 이메일 | H1: 주요취급품목 | I1: 비고
A2: V-001 | B2: OO텍스타일 | C2: 제조 | D2: KR | E2: 홍OO | F2: 02-000-0001 | G2: a@vendor.com | H2: 커버 원단/봉제 | I2: 예시 데이터
A3: V-002 | B3: OO폼 | C3: 제조 | D3: KR | E3: 강OO | F3: 02-000-0002 | G3: b@vendor.com | H3: 폼 | I3: 예시 데이터
A4: V-003 | B4: OO전자 | C4: OEM/ODM | D4: CN | E4: 왕OO | F4: +86-000 | G4: c@vendor.com | H4: 컨트롤러/어댑터/IoT | I4: 예시 데이터
A5: V-004 | B5: OO패키지 | C5: 인쇄 | D5: KR | E5: 송OO | F5: 031-000-0004 | G5: d@vendor.com | H5: 박스/라벨/매뉴얼 | I5: 예시 데이터
A6: V-005 | B6: (자체개발) | C6: 소프트웨어 | D6: KR | E6: - | F6: - | G6: - | H6: 앱/서버 | I6: 예시 데이터

Sheet 담당자마스터
A1: 담당자ID | B1: 이름 | C1: 부서 | D1: 직책 | E1: 이메일 | F1: 연락처 | G1: 비고
A2: E-001 | B2: 김OO | C2: 상품기획 | D2: PM | E2: pm@company.com | F2: 010-0000-0001 | G2: 예시 데이터
A3: E-002 | B3: 이OO | C3: 커버개발 | D3: 과장 | E3: cover@company.com | F3: 010-0000-0002 | G3: 예시 데이터
A4: E-003 | B4: 박OO | C4: H/W개발 | D4: 차장 | E4: hw@company.com | F4: 010-0000-0003 | G4: 예시 데이터
A5: E-004 | B5: 최OO | C5: S/W개발 | D5: 팀장 | E5: sw@company.com | F5: 010-0000-0004 | G5: 예시 데이터
A6: E-005 | B6: 정OO | C6: 구매/포장 | D6: 대리 | E6: pkg@company.com | F6: 010-0000-0005 | G6: 예시 데이터

Sheet AVL
A1: 품번 | B1: 품명 | C1: 협력사코드 | D1: 협력사명 | E1: 사내담당자ID | F1: 사내담당자 | G1: 승인상태 | H1: 리드타임(일) | I1: MOQ | J1: 단가 | K1: 통화 | L1: 승인일 | M1: 비고
A2: CV-001 | B2: =IF(A2="","",IFERROR(INDEX(품목마스터!$B$2:$B$300,MATCH(A2,품목마스터!$A$2:$A$300,0)),"※미등록")) -> 커버1 (상판) | C2: V-001 | D2: =IF(C2="","",IFERROR(INDEX(협력사마스터!$B$2:$B$300,MATCH(C2,협력사마스터!$A$2:$A$300,0)),"※미등록")) -> OO텍스타일 | E2: E-002 | F2: =IF(E2="","",IFERROR(INDEX(담당자마스터!$B$2:$B$300,MATCH(E2,담당자마스터!$A$2:$A$300,0)),"※미등록")) -> 이OO | G2: 승인 | H2: 30 | I2: 500 | J2: 0 | K2: KRW | L2: 2026-08-01 | M2: 예시 데이터
A3: CV-002 | B3: =IF(A3="","",IFERROR(INDEX(품목마스터!$B$2:$B$300,MATCH(A3,품목마스터!$A$2:$A$300,0)),"※미등록")) -> 커버2 (하판) | C3: V-001 | D3: =IF(C3="","",IFERROR(INDEX(협력사마스터!$B$2:$B$300,MATCH(C3,협력사마스터!$A$2:$A$300,0)),"※미등록")) -> OO텍스타일 | E3: E-002 | F3: =IF(E3="","",IFERROR(INDEX(담당자마스터!$B$2:$B$300,MATCH(E3,담당자마스터!$A$2:$A$300,0)),"※미등록")) -> 이OO | G3: 승인 | H3: 30 | I3: 500 | J3: 0 | K3: KRW | L3: 2026-08-01 | M3: 예시 데이터
A4: CV-010 | B4: =IF(A4="","",IFERROR(INDEX(품목마스터!$B$2:$B$300,MATCH(A4,품목마스터!$A$2:$A$300,0)),"※미등록")) -> 폼 | C4: V-002 | D4: =IF(C4="","",IFERROR(INDEX(협력사마스터!$B$2:$B$300,MATCH(C4,협력사마스터!$A$2:$A$300,0)),"※미등록")) -> OO폼 | E4: E-002 | F4: =IF(E4="","",IFERROR(INDEX(담당자마스터!$B$2:$B$300,MATCH(E4,담당자마스터!$A$2:$A$300,0)),"※미등록")) -> 이OO | G4: 샘플평가 | H4: 21 | I4: 300 | J4: 0 | K4: KRW | M4: 예시 데이터
A5: CV-020 | B5: =IF(A5="","",IFERROR(INDEX(품목마스터!$B$2:$B$300,MATCH(A5,품목마스터!$A$2:$A$300,0)),"※미등록")) -> 로우라벨 (법정표시) | C5: V-004 | D5: =IF(C5="","",IFERROR(INDEX(협력사마스터!$B$2:$B$300,MATCH(C5,협력사마스터!$A$2:$A$300,0)),"※미등록")) -> OO패키지 | E5: E-002 | F5: =IF(E5="","",IFERROR(INDEX(담당자마스터!$B$2:$B$300,MATCH(E5,담당자마스터!$A$2:$A$300,0)),"※미등록")) -> 이OO | G5: 승인 | H5: 10 | I5: 1000 | J5: 0 | K5: KRW | L5: 2026-08-10 | M5: 예시 데이터
A6: CV-021 | B6: =IF(A6="","",IFERROR(INDEX(품목마스터!$B$2:$B$300,MATCH(A6,품목마스터!$A$2:$A$300,0)),"※미등록")) -> 로고라벨 | C6: V-004 | D6: =IF(C6="","",IFERROR(INDEX(협력사마스터!$B$2:$B$300,MATCH(C6,협력사마스터!$A$2:$A$300,0)),"※미등록")) -> OO패키지 | E6: E-002 | F6: =IF(E6="","",IFERROR(INDEX(담당자마스터!$B$2:$B$300,MATCH(E6,담당자마스터!$A$2:$A$300,0)),"※미등록")) -> 이OO | G6: 승인 | H6: 10 | I6: 1000 | J6: 0 | K6: KRW | L6: 2026-08-10 | M6: 예시 데이터
A7: CT-001 | B7: =IF(A7="","",IFERROR(INDEX(품목마스터!$B$2:$B$300,MATCH(A7,품목마스터!$A$2:$A$300,0)),"※미등록")) -> 컨트롤러 아세이 (윈도우커버라벨 포함) | C7: V-003 | D7: =IF(C7="","",IFERROR(INDEX(협력사마스터!$B$2:$B$300,MATCH(C7,협력사마스터!$A$2:$A$300,0)),"※미등록")) -> OO전자 | E7: E-003 | F7: =IF(E7="","",IFERROR(INDEX(담당자마스터!$B$2:$B$300,MATCH(E7,담당자마스터!$A$2:$A$300,0)),"※미등록")) -> 박OO | G7: 샘플평가 | H7: 60 | I7: 1000 | J7: 0 | K7: USD | M7: 예시 데이터
A8: CT-002 | B8: =IF(A8="","",IFERROR(INDEX(품목마스터!$B$2:$B$300,MATCH(A8,품목마스터!$A$2:$A$300,0)),"※미등록")) -> 어댑터 | C8: V-003 | D8: =IF(C8="","",IFERROR(INDEX(협력사마스터!$B$2:$B$300,MATCH(C8,협력사마스터!$A$2:$A$300,0)),"※미등록")) -> OO전자 | E8: E-003 | F8: =IF(E8="","",IFERROR(INDEX(담당자마스터!$B$2:$B$300,MATCH(E8,담당자마스터!$A$2:$A$300,0)),"※미등록")) -> 박OO | G8: 승인 | H8: 45 | I8: 1000 | J8: 0 | K8: USD | L8: 2026-07-15 | M8: 예시 데이터
A9: CT-003 | B9: =IF(A9="","",IFERROR(INDEX(품목마스터!$B$2:$B$300,MATCH(A9,품목마스터!$A$2:$A$300,0)),"※미등록")) -> 에어호스 | C9: V-003 | D9: =IF(C9="","",IFERROR(INDEX(협력사마스터!$B$2:$B$300,MATCH(C9,협력사마스터!$A$2:$A$300,0)),"※미등록")) -> OO전자 | E9: E-003 | F9: =IF(E9="","",IFERROR(INDEX(담당자마스터!$B$2:$B$300,MATCH(E9,담당자마스터!$A$2:$A$300,0)),"※미등록")) -> 박OO | G9: 승인 | H9: 45 | I9: 2000 | J9: 0 | K9: USD | L9: 2026-07-15 | M9: 예시 데이터
A10: CT-004 | B10: =IF(A10="","",IFERROR(INDEX(품목마스터!$B$2:$B$300,MATCH(A10,품목마스터!$A$2:$A$300,0)),"※미등록")) -> 매뉴얼 | C10: V-004 | D10: =IF(C10="","",IFERROR(INDEX(협력사마스터!$B$2:$B$300,MATCH(C10,협력사마스터!$A$2:$A$300,0)),"※미등록")) -> OO패키지 | E10: E-003 | F10: =IF(E10="","",IFERROR(INDEX(담당자마스터!$B$2:$B$300,MATCH(E10,담당자마스터!$A$2:$A$300,0)),"※미등록")) -> 박OO | G10: 후보 | H10: 7 | I10: 1000 | J10: 0 | K10: KRW | M10: 예시 데이터
A11: CT-005 | B11: =IF(A11="","",IFERROR(INDEX(품목마스터!$B$2:$B$300,MATCH(A11,품목마스터!$A$2:$A$300,0)),"※미등록")) -> IoT Stick | C11: V-003 | D11: =IF(C11="","",IFERROR(INDEX(협력사마스터!$B$2:$B$300,MATCH(C11,협력사마스터!$A$2:$A$300,0)),"※미등록")) -> OO전자 | E11: E-004 | F11: =IF(E11="","",IFERROR(INDEX(담당자마스터!$B$2:$B$300,MATCH(E11,담당자마스터!$A$2:$A$300,0)),"※미등록")) -> 최OO | G11: 샘플평가 | H11: 60 | I11: 500 | J11: 0 | K11: USD | M11: 예시 데이터
A12: CT-006 | B12: =IF(A12="","",IFERROR(INDEX(품목마스터!$B$2:$B$300,MATCH(A12,품목마스터!$A$2:$A$300,0)),"※미등록")) -> 컨트롤러 포장박스 | C12: V-004 | D12: =IF(C12="","",IFERROR(INDEX(협력사마스터!$B$2:$B$300,MATCH(C12,협력사마스터!$A$2:$A$300,0)),"※미등록")) -> OO패키지 | E12: E-005 | F12: =IF(E12="","",IFERROR(INDEX(담당자마스터!$B$2:$B$300,MATCH(E12,담당자마스터!$A$2:$A$300,0)),"※미등록")) -> 정OO | G12: 승인 | H12: 14 | I12: 1000 | J12: 0 | K12: KRW | L12: 2026-08-05 | M12: 예시 데이터
A13: PK-010 | B13: =IF(A13="","",IFERROR(INDEX(품목마스터!$B$2:$B$300,MATCH(A13,품목마스터!$A$2:$A$300,0)),"※미등록")) -> 완제품 포장박스 | C13: V-004 | D13: =IF(C13="","",IFERROR(INDEX(협력사마스터!$B$2:$B$300,MATCH(C13,협력사마스터!$A$2:$A$300,0)),"※미등록")) -> OO패키지 | E13: E-005 | F13: =IF(E13="","",IFERROR(INDEX(담당자마스터!$B$2:$B$300,MATCH(E13,담당자마스터!$A$2:$A$300,0)),"※미등록")) -> 정OO | G13: 승인 | H13: 14 | I13: 500 | J13: 0 | K13: KRW | L13: 2026-08-05 | M13: 예시 데이터
A14: PK-011 | B14: =IF(A14="","",IFERROR(INDEX(품목마스터!$B$2:$B$300,MATCH(A14,품목마스터!$A$2:$A$300,0)),"※미등록")) -> 포장비닐 | C14: V-004 | D14: =IF(C14="","",IFERROR(INDEX(협력사마스터!$B$2:$B$300,MATCH(C14,협력사마스터!$A$2:$A$300,0)),"※미등록")) -> OO패키지 | E14: E-005 | F14: =IF(E14="","",IFERROR(INDEX(담당자마스터!$B$2:$B$300,MATCH(E14,담당자마스터!$A$2:$A$300,0)),"※미등록")) -> 정OO | G14: 후보 | H14: 14 | I14: 1000 | J14: 0 | K14: KRW | M14: 예시 데이터
A15: SW-001 | B15: =IF(A15="","",IFERROR(INDEX(품목마스터!$B$2:$B$300,MATCH(A15,품목마스터!$A$2:$A$300,0)),"※미등록")) -> Android 앱 | C15: V-005 | D15: =IF(C15="","",IFERROR(INDEX(협력사마스터!$B$2:$B$300,MATCH(C15,협력사마스터!$A$2:$A$300,0)),"※미등록")) -> (자체개발) | E15: E-004 | F15: =IF(E15="","",IFERROR(INDEX(담당자마스터!$B$2:$B$300,MATCH(E15,담당자마스터!$A$2:$A$300,0)),"※미등록")) -> 최OO | G15: 승인 | H15: 0 | I15: 0 | J15: 0 | K15: - | M15: 자체개발
A16: SW-002 | B16: =IF(A16="","",IFERROR(INDEX(품목마스터!$B$2:$B$300,MATCH(A16,품목마스터!$A$2:$A$300,0)),"※미등록")) -> iOS 앱 | C16: V-005 | D16: =IF(C16="","",IFERROR(INDEX(협력사마스터!$B$2:$B$300,MATCH(C16,협력사마스터!$A$2:$A$300,0)),"※미등록")) -> (자체개발) | E16: E-004 | F16: =IF(E16="","",IFERROR(INDEX(담당자마스터!$B$2:$B$300,MATCH(E16,담당자마스터!$A$2:$A$300,0)),"※미등록")) -> 최OO | G16: 승인 | H16: 0 | I16: 0 | J16: 0 | K16: - | M16: 자체개발
A17: SW-003 | B17: =IF(A17="","",IFERROR(INDEX(품목마스터!$B$2:$B$300,MATCH(A17,품목마스터!$A$2:$A$300,0)),"※미등록")) -> 서버 - KR 리전 | C17: V-005 | D17: =IF(C17="","",IFERROR(INDEX(협력사마스터!$B$2:$B$300,MATCH(C17,협력사마스터!$A$2:$A$300,0)),"※미등록")) -> (자체개발) | E17: E-004 | F17: =IF(E17="","",IFERROR(INDEX(담당자마스터!$B$2:$B$300,MATCH(E17,담당자마스터!$A$2:$A$300,0)),"※미등록")) -> 최OO | G17: 승인 | H17: 0 | I17: 0 | J17: 0 | K17: - | M17: 자체개발
B18: =IF(A18="","",IFERROR(INDEX(품목마스터!$B$2:$B$300,MATCH(A18,품목마스터!$A$2:$A$300,0)),"※미등록")) | D18: =IF(C18="","",IFERROR(INDEX(협력사마스터!$B$2:$B$300,MATCH(C18,협력사마스터!$A$2:$A$300,0)),"※미등록")) | F18: =IF(E18="","",IFERROR(INDEX(담당자마스터!$B$2:$B$300,MATCH(E18,담당자마스터!$A$2:$A$300,0)),"※미등록"))
B19: =IF(A19="","",IFERROR(INDEX(품목마스터!$B$2:$B$300,MATCH(A19,품목마스터!$A$2:$A$300,0)),"※미등록")) | D19: =IF(C19="","",IFERROR(INDEX(협력사마스터!$B$2:$B$300,MATCH(C19,협력사마스터!$A$2:$A$300,0)),"※미등록")) | F19: =IF(E19="","",IFERROR(INDEX(담당자마스터!$B$2:$B$300,MATCH(E19,담당자마스터!$A$2:$A$300,0)),"※미등록"))
B20: =IF(A20="","",IFERROR(INDEX(품목마스터!$B$2:$B$300,MATCH(A20,품목마스터!$A$2:$A$300,0)),"※미등록")) | D20: =IF(C20="","",IFERROR(INDEX(협력사마스터!$B$2:$B$300,MATCH(C20,협력사마스터!$A$2:$A$300,0)),"※미등록")) | F20: =IF(E20="","",IFERROR(INDEX(담당자마스터!$B$2:$B$300,MATCH(E20,담당자마스터!$A$2:$A$300,0)),"※미등록"))
B21: =IF(A21="","",IFERROR(INDEX(품목마스터!$B$2:$B$300,MATCH(A21,품목마스터!$A$2:$A$300,0)),"※미등록")) | D21: =IF(C21="","",IFERROR(INDEX(협력사마스터!$B$2:$B$300,MATCH(C21,협력사마스터!$A$2:$A$300,0)),"※미등록")) | F21: =IF(E21="","",IFERROR(INDEX(담당자마스터!$B$2:$B$300,MATCH(E21,담당자마스터!$A$2:$A$300,0)),"※미등록"))
B22: =IF(A22="","",IFERROR(INDEX(품목마스터!$B$2:$B$300,MATCH(A22,품목마스터!$A$2:$A$300,0)),"※미등록")) | D22: =IF(C22="","",IFERROR(INDEX(협력사마스터!$B$2:$B$300,MATCH(C22,협력사마스터!$A$2:$A$300,0)),"※미등록")) | F22: =IF(E22="","",IFERROR(INDEX(담당자마스터!$B$2:$B$300,MATCH(E22,담당자마스터!$A$2:$A$300,0)),"※미등록"))
B23: =IF(A23="","",IFERROR(INDEX(품목마스터!$B$2:$B$300,MATCH(A23,품목마스터!$A$2:$A$300,0)),"※미등록")) | D23: =IF(C23="","",IFERROR(INDEX(협력사마스터!$B$2:$B$300,MATCH(C23,협력사마스터!$A$2:$A$300,0)),"※미등록")) | F23: =IF(E23="","",IFERROR(INDEX(담당자마스터!$B$2:$B$300,MATCH(E23,담당자마스터!$A$2:$A$300,0)),"※미등록"))
B24: =IF(A24="","",IFERROR(INDEX(품목마스터!$B$2:$B$300,MATCH(A24,품목마스터!$A$2:$A$300,0)),"※미등록")) | D24: =IF(C24="","",IFERROR(INDEX(협력사마스터!$B$2:$B$300,MATCH(C24,협력사마스터!$A$2:$A$300,0)),"※미등록")) | F24: =IF(E24="","",IFERROR(INDEX(담당자마스터!$B$2:$B$300,MATCH(E24,담당자마스터!$A$2:$A$300,0)),"※미등록"))
B25: =IF(A25="","",IFERROR(INDEX(품목마스터!$B$2:$B$300,MATCH(A25,품목마스터!$A$2:$A$300,0)),"※미등록")) | D25: =IF(C25="","",IFERROR(INDEX(협력사마스터!$B$2:$B$300,MATCH(C25,협력사마스터!$A$2:$A$300,0)),"※미등록")) | F25: =IF(E25="","",IFERROR(INDEX(담당자마스터!$B$2:$B$300,MATCH(E25,담당자마스터!$A$2:$A$300,0)),"※미등록"))
B26: =IF(A26="","",IFERROR(INDEX(품목마스터!$B$2:$B$300,MATCH(A26,품목마스터!$A$2:$A$300,0)),"※미등록")) | D26: =IF(C26="","",IFERROR(INDEX(협력사마스터!$B$2:$B$300,MATCH(C26,협력사마스터!$A$2:$A$300,0)),"※미등록")) | F26: =IF(E26="","",IFERROR(INDEX(담당자마스터!$B$2:$B$300,MATCH(E26,담당자마스터!$A$2:$A$300,0)),"※미등록"))
B27: =IF(A27="","",IFERROR(INDEX(품목마스터!$B$2:$B$300,MATCH(A27,품목마스터!$A$2:$A$300,0)),"※미등록")) | D27: =IF(C27="","",IFERROR(INDEX(협력사마스터!$B$2:$B$300,MATCH(C27,협력사마스터!$A$2:$A$300,0)),"※미등록")) | F27: =IF(E27="","",IFERROR(INDEX(담당자마스터!$B$2:$B$300,MATCH(E27,담당자마스터!$A$2:$A$300,0)),"※미등록"))
B28: =IF(A28="","",IFERROR(INDEX(품목마스터!$B$2:$B$300,MATCH(A28,품목마스터!$A$2:$A$300,0)),"※미등록")) | D28: =IF(C28="","",IFERROR(INDEX(협력사마스터!$B$2:$B$300,MATCH(C28,협력사마스터!$A$2:$A$300,0)),"※미등록")) | F28: =IF(E28="","",IFERROR(INDEX(담당자마스터!$B$2:$B$300,MATCH(E28,담당자마스터!$A$2:$A$300,0)),"※미등록"))
B29: =IF(A29="","",IFERROR(INDEX(품목마스터!$B$2:$B$300,MATCH(A29,품목마스터!$A$2:$A$300,0)),"※미등록")) | D29: =IF(C29="","",IFERROR(INDEX(협력사마스터!$B$2:$B$300,MATCH(C29,협력사마스터!$A$2:$A$300,0)),"※미등록")) | F29: =IF(E29="","",IFERROR(INDEX(담당자마스터!$B$2:$B$300,MATCH(E29,담당자마스터!$A$2:$A$300,0)),"※미등록"))
... B300: =IF(A300="","",IFERROR(INDEX(품목마스터!$B$2:$B$300,MATCH(A300,품목마스터!$A$2:$A$300,0)),"※미등록")) | D300: =IF(C300="","",IFERROR(INDEX(협력사마스터!$B$2:$B$300,MATCH(C300,협력사마스터!$A$2:$A$300,0)),"※미등록")) | F300: =IF(E300="","",IFERROR(INDEX(담당자마스터!$B$2:$B$300,MATCH(E300,담당자마스터!$A$2:$A$300,0)),"※미등록"))

Sheet NPI진행현황
A1: 상품코드 | B1: 품번 | C1: 품명 | D1: 담당자ID | E1: 담당자 | F1: 개발단계 | G1: 완료율 | H1: 시작일 | I1: 목표일 | J1: 이슈상태 | K1: 이슈내용 | L1: 다음 마일스톤 | M1: 최종업데이트 | N1: 비고
A2: MAT-001 | B2: CV-001 | C2: =IF(B2="","",IFERROR(INDEX(품목마스터!$B$2:$B$300,MATCH(B2,품목마스터!$A$2:$A$300,0)),"※미등록")) -> 커버1 (상판) | D2: E-002 | E2: =IF(D2="","",IFERROR(INDEX(담당자마스터!$B$2:$B$300,MATCH(D2,담당자마스터!$A$2:$A$300,0)),"※미등록")) -> 이OO | F2: DVT | G2: 0.8 | H2: 2026-06-01 | I2: 2026-10-15 | J2: 없음 | L2: DVT 세탁 내구 테스트 완료 | M2: 2026-09-01 | N2: 예시
A3: MAT-001 | B3: CV-002 | C3: =IF(B3="","",IFERROR(INDEX(품목마스터!$B$2:$B$300,MATCH(B3,품목마스터!$A$2:$A$300,0)),"※미등록")) -> 커버2 (하판) | D3: E-002 | E3: =IF(D3="","",IFERROR(INDEX(담당자마스터!$B$2:$B$300,MATCH(D3,담당자마스터!$A$2:$A$300,0)),"※미등록")) -> 이OO | F3: DVT | G3: 0.8 | H3: 2026-06-01 | I3: 2026-10-15 | J3: 없음 | M3: 2026-09-01 | N3: 예시
A4: MAT-001 | B4: CV-010 | C4: =IF(B4="","",IFERROR(INDEX(품목마스터!$B$2:$B$300,MATCH(B4,품목마스터!$A$2:$A$300,0)),"※미등록")) -> 폼 | D4: E-002 | E4: =IF(D4="","",IFERROR(INDEX(담당자마스터!$B$2:$B$300,MATCH(D4,담당자마스터!$A$2:$A$300,0)),"※미등록")) -> 이OO | F4: EVT | G4: 0.4 | H4: 2026-07-01 | I4: 2026-10-30 | J4: 진행중 | K4: 밀도 편차 발생, 2차 샘플 대기 | L4: 2차 샘플 입고 9/20 | M4: 2026-09-01 | N4: 예시
A5: MAT-001 | B5: CV-020 | C5: =IF(B5="","",IFERROR(INDEX(품목마스터!$B$2:$B$300,MATCH(B5,품목마스터!$A$2:$A$300,0)),"※미등록")) -> 로우라벨 (법정표시) | D5: E-002 | E5: =IF(D5="","",IFERROR(INDEX(담당자마스터!$B$2:$B$300,MATCH(D5,담당자마스터!$A$2:$A$300,0)),"※미등록")) -> 이OO | F5: PVT | G5: 0.9 | H5: 2026-06-15 | I5: 2026-09-30 | J5: 없음 | L5: 법정표시 문구 최종 검토 | M5: 2026-09-01 | N5: 예시
A6: MAT-001 | B6: CV-021 | C6: =IF(B6="","",IFERROR(INDEX(품목마스터!$B$2:$B$300,MATCH(B6,품목마스터!$A$2:$A$300,0)),"※미등록")) -> 로고라벨 | D6: E-002 | E6: =IF(D6="","",IFERROR(INDEX(담당자마스터!$B$2:$B$300,MATCH(D6,담당자마스터!$A$2:$A$300,0)),"※미등록")) -> 이OO | F6: MP(양산) | G6: 1 | H6: 2026-05-01 | I6: 2026-08-30 | J6: 해결 | L6: - | M6: 2026-08-30 | N6: 예시
A7: MAT-001 | B7: CT-001 | C7: =IF(B7="","",IFERROR(INDEX(품목마스터!$B$2:$B$300,MATCH(B7,품목마스터!$A$2:$A$300,0)),"※미등록")) -> 컨트롤러 아세이 (윈도우커버라벨 포함) | D7: E-003 | E7: =IF(D7="","",IFERROR(INDEX(담당자마스터!$B$2:$B$300,MATCH(D7,담당자마스터!$A$2:$A$300,0)),"※미등록")) -> 박OO | F7: EVT | G7: 0.5 | H7: 2026-05-01 | I7: 2026-11-15 | J7: 지연 | K7: 윈도우커버라벨 인쇄 색상 불일치 | L7: EVT2 샘플 검증 | M7: 2026-09-01 | N7: 예시
A8: MAT-001 | B8: CT-002 | C8: =IF(B8="","",IFERROR(INDEX(품목마스터!$B$2:$B$300,MATCH(B8,품목마스터!$A$2:$A$300,0)),"※미등록")) -> 어댑터 | D8: E-003 | E8: =IF(D8="","",IFERROR(INDEX(담당자마스터!$B$2:$B$300,MATCH(D8,담당자마스터!$A$2:$A$300,0)),"※미등록")) -> 박OO | F8: MP(양산) | G8: 1 | H8: 2026-04-01 | I8: 2026-07-15 | J8: 없음 | L8: - | M8: 2026-07-15 | N8: 예시
A9: MAT-001 | B9: CT-003 | C9: =IF(B9="","",IFERROR(INDEX(품목마스터!$B$2:$B$300,MATCH(B9,품목마스터!$A$2:$A$300,0)),"※미등록")) -> 에어호스 | D9: E-003 | E9: =IF(D9="","",IFERROR(INDEX(담당자마스터!$B$2:$B$300,MATCH(D9,담당자마스터!$A$2:$A$300,0)),"※미등록")) -> 박OO | F9: MP(양산) | G9: 1 | H9: 2026-04-01 | I9: 2026-07-15 | J9: 없음 | L9: - | M9: 2026-07-15 | N9: 예시
A10: MAT-001 | B10: CT-004 | C10: =IF(B10="","",IFERROR(INDEX(품목마스터!$B$2:$B$300,MATCH(B10,품목마스터!$A$2:$A$300,0)),"※미등록")) -> 매뉴얼 | D10: E-003 | E10: =IF(D10="","",IFERROR(INDEX(담당자마스터!$B$2:$B$300,MATCH(D10,담당자마스터!$A$2:$A$300,0)),"※미등록")) -> 박OO | F10: 기획 | G10: 0.2 | H10: 2026-08-01 | I10: 2026-11-01 | J10: 없음 | L10: 초안 작성 | M10: 2026-09-01 | N10: 예시
A11: MAT-001 | B11: CT-005 | C11: =IF(B11="","",IFERROR(INDEX(품목마스터!$B$2:$B$300,MATCH(B11,품목마스터!$A$2:$A$300,0)),"※미등록")) -> IoT Stick | D11: E-004 | E11: =IF(D11="","",IFERROR(INDEX(담당자마스터!$B$2:$B$300,MATCH(D11,담당자마스터!$A$2:$A$300,0)),"※미등록")) -> 최OO | F11: DVT | G11: 0.6 | H11: 2026-05-01 | I11: 2026-11-01 | J11: 진행중 | K11: Wi-Fi 연결 안정성 개선 중 | L11: FW 1.2 테스트 | M11: 2026-09-01 | N11: 예시
A12: MAT-001 | B12: CT-006 | C12: =IF(B12="","",IFERROR(INDEX(품목마스터!$B$2:$B$300,MATCH(B12,품목마스터!$A$2:$A$300,0)),"※미등록")) -> 컨트롤러 포장박스 | D12: E-005 | E12: =IF(D12="","",IFERROR(INDEX(담당자마스터!$B$2:$B$300,MATCH(D12,담당자마스터!$A$2:$A$300,0)),"※미등록")) -> 정OO | F12: PVT | G12: 0.9 | H12: 2026-07-01 | I12: 2026-10-01 | J12: 없음 | M12: 2026-09-01 | N12: 예시
A13: MAT-001 | B13: PK-001 | C13: =IF(B13="","",IFERROR(INDEX(품목마스터!$B$2:$B$300,MATCH(B13,품목마스터!$A$2:$A$300,0)),"※미등록")) -> 포장방식 A | D13: E-005 | E13: =IF(D13="","",IFERROR(INDEX(담당자마스터!$B$2:$B$300,MATCH(D13,담당자마스터!$A$2:$A$300,0)),"※미등록")) -> 정OO | F13: DVT | G13: 0.7 | H13: 2026-07-01 | I13: 2026-10-15 | J13: 없음 | L13: 낙하 테스트 | M13: 2026-09-01 | N13: 예시
A14: MAT-001 | B14: PK-010 | C14: =IF(B14="","",IFERROR(INDEX(품목마스터!$B$2:$B$300,MATCH(B14,품목마스터!$A$2:$A$300,0)),"※미등록")) -> 완제품 포장박스 | D14: E-005 | E14: =IF(D14="","",IFERROR(INDEX(담당자마스터!$B$2:$B$300,MATCH(D14,담당자마스터!$A$2:$A$300,0)),"※미등록")) -> 정OO | F14: PVT | G14: 0.9 | H14: 2026-07-01 | I14: 2026-10-01 | J14: 없음 | M14: 2026-09-01 | N14: 예시
A15: MAT-001 | B15: PK-011 | C15: =IF(B15="","",IFERROR(INDEX(품목마스터!$B$2:$B$300,MATCH(B15,품목마스터!$A$2:$A$300,0)),"※미등록")) -> 포장비닐 | D15: E-005 | E15: =IF(D15="","",IFERROR(INDEX(담당자마스터!$B$2:$B$300,MATCH(D15,담당자마스터!$A$2:$A$300,0)),"※미등록")) -> 정OO | F15: EVT | G15: 0.3 | H15: 2026-08-01 | I15: 2026-10-15 | J15: 없음 | L15: 협력사 선정 | M15: 2026-09-01 | N15: 예시
A16: MAT-001 | B16: SW-001 | C16: =IF(B16="","",IFERROR(INDEX(품목마스터!$B$2:$B$300,MATCH(B16,품목마스터!$A$2:$A$300,0)),"※미등록")) -> Android 앱 | D16: E-004 | E16: =IF(D16="","",IFERROR(INDEX(담당자마스터!$B$2:$B$300,MATCH(D16,담당자마스터!$A$2:$A$300,0)),"※미등록")) -> 최OO | F16: DVT | G16: 0.7 | H16: 2026-05-01 | I16: 2026-11-15 | J16: 없음 | L16: 베타 배포 | M16: 2026-09-01 | N16: 예시
A17: MAT-001 | B17: SW-002 | C17: =IF(B17="","",IFERROR(INDEX(품목마스터!$B$2:$B$300,MATCH(B17,품목마스터!$A$2:$A$300,0)),"※미등록")) -> iOS 앱 | D17: E-004 | E17: =IF(D17="","",IFERROR(INDEX(담당자마스터!$B$2:$B$300,MATCH(D17,담당자마스터!$A$2:$A$300,0)),"※미등록")) -> 최OO | F17: DVT | G17: 0.6 | H17: 2026-05-01 | I17: 2026-11-15 | J17: 진행중 | K17: 앱스토어 심사 대응 | L17: TestFlight 배포 | M17: 2026-09-01 | N17: 예시
A18: MAT-001 | B18: SW-003 | C18: =IF(B18="","",IFERROR(INDEX(품목마스터!$B$2:$B$300,MATCH(B18,품목마스터!$A$2:$A$300,0)),"※미등록")) -> 서버 - KR 리전 | D18: E-004 | E18: =IF(D18="","",IFERROR(INDEX(담당자마스터!$B$2:$B$300,MATCH(D18,담당자마스터!$A$2:$A$300,0)),"※미등록")) -> 최OO | F18: PVT | G18: 0.85 | H18: 2026-04-01 | I18: 2026-11-01 | J18: 없음 | L18: 부하 테스트 | M18: 2026-09-01 | N18: 예시
C19: =IF(B19="","",IFERROR(INDEX(품목마스터!$B$2:$B$300,MATCH(B19,품목마스터!$A$2:$A$300,0)),"※미등록")) | E19: =IF(D19="","",IFERROR(INDEX(담당자마스터!$B$2:$B$300,MATCH(D19,담당자마스터!$A$2:$A$300,0)),"※미등록"))
C20: =IF(B20="","",IFERROR(INDEX(품목마스터!$B$2:$B$300,MATCH(B20,품목마스터!$A$2:$A$300,0)),"※미등록")) | E20: =IF(D20="","",IFERROR(INDEX(담당자마스터!$B$2:$B$300,MATCH(D20,담당자마스터!$A$2:$A$300,0)),"※미등록"))
C21: =IF(B21="","",IFERROR(INDEX(품목마스터!$B$2:$B$300,MATCH(B21,품목마스터!$A$2:$A$300,0)),"※미등록")) | E21: =IF(D21="","",IFERROR(INDEX(담당자마스터!$B$2:$B$300,MATCH(D21,담당자마스터!$A$2:$A$300,0)),"※미등록"))
C22: =IF(B22="","",IFERROR(INDEX(품목마스터!$B$2:$B$300,MATCH(B22,품목마스터!$A$2:$A$300,0)),"※미등록")) | E22: =IF(D22="","",IFERROR(INDEX(담당자마스터!$B$2:$B$300,MATCH(D22,담당자마스터!$A$2:$A$300,0)),"※미등록"))
C23: =IF(B23="","",IFERROR(INDEX(품목마스터!$B$2:$B$300,MATCH(B23,품목마스터!$A$2:$A$300,0)),"※미등록")) | E23: =IF(D23="","",IFERROR(INDEX(담당자마스터!$B$2:$B$300,MATCH(D23,담당자마스터!$A$2:$A$300,0)),"※미등록"))
C24: =IF(B24="","",IFERROR(INDEX(품목마스터!$B$2:$B$300,MATCH(B24,품목마스터!$A$2:$A$300,0)),"※미등록")) | E24: =IF(D24="","",IFERROR(INDEX(담당자마스터!$B$2:$B$300,MATCH(D24,담당자마스터!$A$2:$A$300,0)),"※미등록"))
C25: =IF(B25="","",IFERROR(INDEX(품목마스터!$B$2:$B$300,MATCH(B25,품목마스터!$A$2:$A$300,0)),"※미등록")) | E25: =IF(D25="","",IFERROR(INDEX(담당자마스터!$B$2:$B$300,MATCH(D25,담당자마스터!$A$2:$A$300,0)),"※미등록"))
C26: =IF(B26="","",IFERROR(INDEX(품목마스터!$B$2:$B$300,MATCH(B26,품목마스터!$A$2:$A$300,0)),"※미등록")) | E26: =IF(D26="","",IFERROR(INDEX(담당자마스터!$B$2:$B$300,MATCH(D26,담당자마스터!$A$2:$A$300,0)),"※미등록"))
C27: =IF(B27="","",IFERROR(INDEX(품목마스터!$B$2:$B$300,MATCH(B27,품목마스터!$A$2:$A$300,0)),"※미등록")) | E27: =IF(D27="","",IFERROR(INDEX(담당자마스터!$B$2:$B$300,MATCH(D27,담당자마스터!$A$2:$A$300,0)),"※미등록"))
C28: =IF(B28="","",IFERROR(INDEX(품목마스터!$B$2:$B$300,MATCH(B28,품목마스터!$A$2:$A$300,0)),"※미등록")) | E28: =IF(D28="","",IFERROR(INDEX(담당자마스터!$B$2:$B$300,MATCH(D28,담당자마스터!$A$2:$A$300,0)),"※미등록"))
C29: =IF(B29="","",IFERROR(INDEX(품목마스터!$B$2:$B$300,MATCH(B29,품목마스터!$A$2:$A$300,0)),"※미등록")) | E29: =IF(D29="","",IFERROR(INDEX(담당자마스터!$B$2:$B$300,MATCH(D29,담당자마스터!$A$2:$A$300,0)),"※미등록"))
C30: =IF(B30="","",IFERROR(INDEX(품목마스터!$B$2:$B$300,MATCH(B30,품목마스터!$A$2:$A$300,0)),"※미등록")) | E30: =IF(D30="","",IFERROR(INDEX(담당자마스터!$B$2:$B$300,MATCH(D30,담당자마스터!$A$2:$A$300,0)),"※미등록"))
... C300: =IF(B300="","",IFERROR(INDEX(품목마스터!$B$2:$B$300,MATCH(B300,품목마스터!$A$2:$A$300,0)),"※미등록")) | E300: =IF(D300="","",IFERROR(INDEX(담당자마스터!$B$2:$B$300,MATCH(D300,담당자마스터!$A$2:$A$300,0)),"※미등록"))

Sheet 상품별완성률
A1: 상품코드 | B1: 상품명 | C1: 상태 | D1: 등록 부품수 | E1: 전체 완성률 | F1: 커버 | G1: 컨트롤러 | H1: 포장 | I1: APP | J1: 기획 | K1: EVT | L1: DVT | M1: PVT | N1: MP(양산) | O1: 진행중/지연 이슈
A2: =IF(상품마스터!A2="","",상품마스터!A2) -> MAT-001 | B2: =IF($A2="","",상품마스터!B2) -> 에어매트리스 A (커버 2분리) | C2: =IF($A2="","",상품마스터!D2) -> 개발 | D2: =IF($A2="","",COUNTIFS(NPI진행현황!$A$2:$A$300,$A2)) -> 17 | E2: =IF($A2="","",IFERROR(AVERAGEIFS(NPI진행현황!$G$2:$G$300,NPI진행현황!$A$2:$A$300,$A2),"-")) -> 0.71470588 | F2: =IF($A2="","",IFERROR(AVERAGEIFS(NPI진행현황!$G$2:$G$300,NPI진행현황!$A$2:$A$300,$A2,NPI진행현황!$B$2:$B$300,"CV-*"),"-")) -> 0.78 | G2: =IF($A2="","",IFERROR(AVERAGEIFS(NPI진행현황!$G$2:$G$300,NPI진행현황!$A$2:$A$300,$A2,NPI진행현황!$B$2:$B$300,"CT-*"),"-")) -> 0.7 | H2: =IF($A2="","",IFERROR(AVERAGEIFS(NPI진행현황!$G$2:$G$300,NPI진행현황!$A$2:$A$300,$A2,NPI진행현황!$B$2:$B$300,"PK-*"),"-")) -> 0.63333333 | I2: =IF($A2="","",IFERROR(AVERAGEIFS(NPI진행현황!$G$2:$G$300,NPI진행현황!$A$2:$A$300,$A2,NPI진행현황!$B$2:$B$300,"SW-*"),"-")) -> 0.71666667 | J2: =IF($A2="","",COUNTIFS(NPI진행현황!$A$2:$A$300,$A2,NPI진행현황!$F$2:$F$300,"기획")) -> 1 | K2: =IF($A2="","",COUNTIFS(NPI진행현황!$A$2:$A$300,$A2,NPI진행현황!$F$2:$F$300,"EVT")) -> 3 | L2: =IF($A2="","",COUNTIFS(NPI진행현황!$A$2:$A$300,$A2,NPI진행현황!$F$2:$F$300,"DVT")) -> 6 | M2: =IF($A2="","",COUNTIFS(NPI진행현황!$A$2:$A$300,$A2,NPI진행현황!$F$2:$F$300,"PVT")) -> 4 | N2: =IF($A2="","",COUNTIFS(NPI진행현황!$A$2:$A$300,$A2,NPI진행현황!$F$2:$F$300,"MP(양산)")) -> 3 | O2: =IF($A2="","",COUNTIFS(NPI진행현황!$A$2:$A$300,$A2,NPI진행현황!$J$2:$J$300,"진행중")+COUNTIFS(NPI진행현황!$A$2:$A$300,$A2,NPI진행현황!$J$2:$J$300,"지연")) -> 4
A3: =IF(상품마스터!A3="","",상품마스터!A3) -> MAT-002 | B3: =IF($A3="","",상품마스터!B3) -> 에어매트리스 B (커버 3분리) | C3: =IF($A3="","",상품마스터!D3) -> 기획 | D3: =IF($A3="","",COUNTIFS(NPI진행현황!$A$2:$A$300,$A3)) -> 0 | E3: =IF($A3="","",IFERROR(AVERAGEIFS(NPI진행현황!$G$2:$G$300,NPI진행현황!$A$2:$A$300,$A3),"-")) -> - | F3: =IF($A3="","",IFERROR(AVERAGEIFS(NPI진행현황!$G$2:$G$300,NPI진행현황!$A$2:$A$300,$A3,NPI진행현황!$B$2:$B$300,"CV-*"),"-")) -> - | G3: =IF($A3="","",IFERROR(AVERAGEIFS(NPI진행현황!$G$2:$G$300,NPI진행현황!$A$2:$A$300,$A3,NPI진행현황!$B$2:$B$300,"CT-*"),"-")) -> - | H3: =IF($A3="","",IFERROR(AVERAGEIFS(NPI진행현황!$G$2:$G$300,NPI진행현황!$A$2:$A$300,$A3,NPI진행현황!$B$2:$B$300,"PK-*"),"-")) -> - | I3: =IF($A3="","",IFERROR(AVERAGEIFS(NPI진행현황!$G$2:$G$300,NPI진행현황!$A$2:$A$300,$A3,NPI진행현황!$B$2:$B$300,"SW-*"),"-")) -> - | J3: =IF($A3="","",COUNTIFS(NPI진행현황!$A$2:$A$300,$A3,NPI진행현황!$F$2:$F$300,"기획")) -> 0 | K3: =IF($A3="","",COUNTIFS(NPI진행현황!$A$2:$A$300,$A3,NPI진행현황!$F$2:$F$300,"EVT")) -> 0 | L3: =IF($A3="","",COUNTIFS(NPI진행현황!$A$2:$A$300,$A3,NPI진행현황!$F$2:$F$300,"DVT")) -> 0 | M3: =IF($A3="","",COUNTIFS(NPI진행현황!$A$2:$A$300,$A3,NPI진행현황!$F$2:$F$300,"PVT")) -> 0 | N3: =IF($A3="","",COUNTIFS(NPI진행현황!$A$2:$A$300,$A3,NPI진행현황!$F$2:$F$300,"MP(양산)")) -> 0 | O3: =IF($A3="","",COUNTIFS(NPI진행현황!$A$2:$A$300,$A3,NPI진행현황!$J$2:$J$300,"진행중")+COUNTIFS(NPI진행현황!$A$2:$A$300,$A3,NPI진행현황!$J$2:$J$300,"지연")) -> 0
A4: =IF(상품마스터!A4="","",상품마스터!A4) | B4: =IF($A4="","",상품마스터!B4) | C4: =IF($A4="","",상품마스터!D4) | D4: =IF($A4="","",COUNTIFS(NPI진행현황!$A$2:$A$300,$A4)) | E4: =IF($A4="","",IFERROR(AVERAGEIFS(NPI진행현황!$G$2:$G$300,NPI진행현황!$A$2:$A$300,$A4),"-")) | F4: =IF($A4="","",IFERROR(AVERAGEIFS(NPI진행현황!$G$2:$G$300,NPI진행현황!$A$2:$A$300,$A4,NPI진행현황!$B$2:$B$300,"CV-*"),"-")) | G4: =IF($A4="","",IFERROR(AVERAGEIFS(NPI진행현황!$G$2:$G$300,NPI진행현황!$A$2:$A$300,$A4,NPI진행현황!$B$2:$B$300,"CT-*"),"-")) | H4: =IF($A4="","",IFERROR(AVERAGEIFS(NPI진행현황!$G$2:$G$300,NPI진행현황!$A$2:$A$300,$A4,NPI진행현황!$B$2:$B$300,"PK-*"),"-")) | I4: =IF($A4="","",IFERROR(AVERAGEIFS(NPI진행현황!$G$2:$G$300,NPI진행현황!$A$2:$A$300,$A4,NPI진행현황!$B$2:$B$300,"SW-*"),"-")) | J4: =IF($A4="","",COUNTIFS(NPI진행현황!$A$2:$A$300,$A4,NPI진행현황!$F$2:$F$300,"기획")) | K4: =IF($A4="","",COUNTIFS(NPI진행현황!$A$2:$A$300,$A4,NPI진행현황!$F$2:$F$300,"EVT")) | L4: =IF($A4="","",COUNTIFS(NPI진행현황!$A$2:$A$300,$A4,NPI진행현황!$F$2:$F$300,"DVT")) | M4: =IF($A4="","",COUNTIFS(NPI진행현황!$A$2:$A$300,$A4,NPI진행현황!$F$2:$F$300,"PVT")) | N4: =IF($A4="","",COUNTIFS(NPI진행현황!$A$2:$A$300,$A4,NPI진행현황!$F$2:$F$300,"MP(양산)")) | O4: =IF($A4="","",COUNTIFS(NPI진행현황!$A$2:$A$300,$A4,NPI진행현황!$J$2:$J$300,"진행중")+COUNTIFS(NPI진행현황!$A$2:$A$300,$A4,NPI진행현황!$J$2:$J$300,"지연"))
A5: =IF(상품마스터!A5="","",상품마스터!A5) | B5: =IF($A5="","",상품마스터!B5) | C5: =IF($A5="","",상품마스터!D5) | D5: =IF($A5="","",COUNTIFS(NPI진행현황!$A$2:$A$300,$A5)) | E5: =IF($A5="","",IFERROR(AVERAGEIFS(NPI진행현황!$G$2:$G$300,NPI진행현황!$A$2:$A$300,$A5),"-")) | F5: =IF($A5="","",IFERROR(AVERAGEIFS(NPI진행현황!$G$2:$G$300,NPI진행현황!$A$2:$A$300,$A5,NPI진행현황!$B$2:$B$300,"CV-*"),"-")) | G5: =IF($A5="","",IFERROR(AVERAGEIFS(NPI진행현황!$G$2:$G$300,NPI진행현황!$A$2:$A$300,$A5,NPI진행현황!$B$2:$B$300,"CT-*"),"-")) | H5: =IF($A5="","",IFERROR(AVERAGEIFS(NPI진행현황!$G$2:$G$300,NPI진행현황!$A$2:$A$300,$A5,NPI진행현황!$B$2:$B$300,"PK-*"),"-")) | I5: =IF($A5="","",IFERROR(AVERAGEIFS(NPI진행현황!$G$2:$G$300,NPI진행현황!$A$2:$A$300,$A5,NPI진행현황!$B$2:$B$300,"SW-*"),"-")) | J5: =IF($A5="","",COUNTIFS(NPI진행현황!$A$2:$A$300,$A5,NPI진행현황!$F$2:$F$300,"기획")) | K5: =IF($A5="","",COUNTIFS(NPI진행현황!$A$2:$A$300,$A5,NPI진행현황!$F$2:$F$300,"EVT")) | L5: =IF($A5="","",COUNTIFS(NPI진행현황!$A$2:$A$300,$A5,NPI진행현황!$F$2:$F$300,"DVT")) | M5: =IF($A5="","",COUNTIFS(NPI진행현황!$A$2:$A$300,$A5,NPI진행현황!$F$2:$F$300,"PVT")) | N5: =IF($A5="","",COUNTIFS(NPI진행현황!$A$2:$A$300,$A5,NPI진행현황!$F$2:$F$300,"MP(양산)")) | O5: =IF($A5="","",COUNTIFS(NPI진행현황!$A$2:$A$300,$A5,NPI진행현황!$J$2:$J$300,"진행중")+COUNTIFS(NPI진행현황!$A$2:$A$300,$A5,NPI진행현황!$J$2:$J$300,"지연"))
A6: =IF(상품마스터!A6="","",상품마스터!A6) | B6: =IF($A6="","",상품마스터!B6) | C6: =IF($A6="","",상품마스터!D6) | D6: =IF($A6="","",COUNTIFS(NPI진행현황!$A$2:$A$300,$A6)) | E6: =IF($A6="","",IFERROR(AVERAGEIFS(NPI진행현황!$G$2:$G$300,NPI진행현황!$A$2:$A$300,$A6),"-")) | F6: =IF($A6="","",IFERROR(AVERAGEIFS(NPI진행현황!$G$2:$G$300,NPI진행현황!$A$2:$A$300,$A6,NPI진행현황!$B$2:$B$300,"CV-*"),"-")) | G6: =IF($A6="","",IFERROR(AVERAGEIFS(NPI진행현황!$G$2:$G$300,NPI진행현황!$A$2:$A$300,$A6,NPI진행현황!$B$2:$B$300,"CT-*"),"-")) | H6: =IF($A6="","",IFERROR(AVERAGEIFS(NPI진행현황!$G$2:$G$300,NPI진행현황!$A$2:$A$300,$A6,NPI진행현황!$B$2:$B$300,"PK-*"),"-")) | I6: =IF($A6="","",IFERROR(AVERAGEIFS(NPI진행현황!$G$2:$G$300,NPI진행현황!$A$2:$A$300,$A6,NPI진행현황!$B$2:$B$300,"SW-*"),"-")) | J6: =IF($A6="","",COUNTIFS(NPI진행현황!$A$2:$A$300,$A6,NPI진행현황!$F$2:$F$300,"기획")) | K6: =IF($A6="","",COUNTIFS(NPI진행현황!$A$2:$A$300,$A6,NPI진행현황!$F$2:$F$300,"EVT")) | L6: =IF($A6="","",COUNTIFS(NPI진행현황!$A$2:$A$300,$A6,NPI진행현황!$F$2:$F$300,"DVT")) | M6: =IF($A6="","",COUNTIFS(NPI진행현황!$A$2:$A$300,$A6,NPI진행현황!$F$2:$F$300,"PVT")) | N6: =IF($A6="","",COUNTIFS(NPI진행현황!$A$2:$A$300,$A6,NPI진행현황!$F$2:$F$300,"MP(양산)")) | O6: =IF($A6="","",COUNTIFS(NPI진행현황!$A$2:$A$300,$A6,NPI진행현황!$J$2:$J$300,"진행중")+COUNTIFS(NPI진행현황!$A$2:$A$300,$A6,NPI진행현황!$J$2:$J$300,"지연"))
A7: =IF(상품마스터!A7="","",상품마스터!A7) | B7: =IF($A7="","",상품마스터!B7) | C7: =IF($A7="","",상품마스터!D7) | D7: =IF($A7="","",COUNTIFS(NPI진행현황!$A$2:$A$300,$A7)) | E7: =IF($A7="","",IFERROR(AVERAGEIFS(NPI진행현황!$G$2:$G$300,NPI진행현황!$A$2:$A$300,$A7),"-")) | F7: =IF($A7="","",IFERROR(AVERAGEIFS(NPI진행현황!$G$2:$G$300,NPI진행현황!$A$2:$A$300,$A7,NPI진행현황!$B$2:$B$300,"CV-*"),"-")) | G7: =IF($A7="","",IFERROR(AVERAGEIFS(NPI진행현황!$G$2:$G$300,NPI진행현황!$A$2:$A$300,$A7,NPI진행현황!$B$2:$B$300,"CT-*"),"-")) | H7: =IF($A7="","",IFERROR(AVERAGEIFS(NPI진행현황!$G$2:$G$300,NPI진행현황!$A$2:$A$300,$A7,NPI진행현황!$B$2:$B$300,"PK-*"),"-")) | I7: =IF($A7="","",IFERROR(AVERAGEIFS(NPI진행현황!$G$2:$G$300,NPI진행현황!$A$2:$A$300,$A7,NPI진행현황!$B$2:$B$300,"SW-*"),"-")) | J7: =IF($A7="","",COUNTIFS(NPI진행현황!$A$2:$A$300,$A7,NPI진행현황!$F$2:$F$300,"기획")) | K7: =IF($A7="","",COUNTIFS(NPI진행현황!$A$2:$A$300,$A7,NPI진행현황!$F$2:$F$300,"EVT")) | L7: =IF($A7="","",COUNTIFS(NPI진행현황!$A$2:$A$300,$A7,NPI진행현황!$F$2:$F$300,"DVT")) | M7: =IF($A7="","",COUNTIFS(NPI진행현황!$A$2:$A$300,$A7,NPI진행현황!$F$2:$F$300,"PVT")) | N7: =IF($A7="","",COUNTIFS(NPI진행현황!$A$2:$A$300,$A7,NPI진행현황!$F$2:$F$300,"MP(양산)")) | O7: =IF($A7="","",COUNTIFS(NPI진행현황!$A$2:$A$300,$A7,NPI진행현황!$J$2:$J$300,"진행중")+COUNTIFS(NPI진행현황!$A$2:$A$300,$A7,NPI진행현황!$J$2:$J$300,"지연"))
A8: =IF(상품마스터!A8="","",상품마스터!A8) | B8: =IF($A8="","",상품마스터!B8) | C8: =IF($A8="","",상품마스터!D8) | D8: =IF($A8="","",COUNTIFS(NPI진행현황!$A$2:$A$300,$A8)) | E8: =IF($A8="","",IFERROR(AVERAGEIFS(NPI진행현황!$G$2:$G$300,NPI진행현황!$A$2:$A$300,$A8),"-")) | F8: =IF($A8="","",IFERROR(AVERAGEIFS(NPI진행현황!$G$2:$G$300,NPI진행현황!$A$2:$A$300,$A8,NPI진행현황!$B$2:$B$300,"CV-*"),"-")) | G8: =IF($A8="","",IFERROR(AVERAGEIFS(NPI진행현황!$G$2:$G$300,NPI진행현황!$A$2:$A$300,$A8,NPI진행현황!$B$2:$B$300,"CT-*"),"-")) | H8: =IF($A8="","",IFERROR(AVERAGEIFS(NPI진행현황!$G$2:$G$300,NPI진행현황!$A$2:$A$300,$A8,NPI진행현황!$B$2:$B$300,"PK-*"),"-")) | I8: =IF($A8="","",IFERROR(AVERAGEIFS(NPI진행현황!$G$2:$G$300,NPI진행현황!$A$2:$A$300,$A8,NPI진행현황!$B$2:$B$300,"SW-*"),"-")) | J8: =IF($A8="","",COUNTIFS(NPI진행현황!$A$2:$A$300,$A8,NPI진행현황!$F$2:$F$300,"기획")) | K8: =IF($A8="","",COUNTIFS(NPI진행현황!$A$2:$A$300,$A8,NPI진행현황!$F$2:$F$300,"EVT")) | L8: =IF($A8="","",COUNTIFS(NPI진행현황!$A$2:$A$300,$A8,NPI진행현황!$F$2:$F$300,"DVT")) | M8: =IF($A8="","",COUNTIFS(NPI진행현황!$A$2:$A$300,$A8,NPI진행현황!$F$2:$F$300,"PVT")) | N8: =IF($A8="","",COUNTIFS(NPI진행현황!$A$2:$A$300,$A8,NPI진행현황!$F$2:$F$300,"MP(양산)")) | O8: =IF($A8="","",COUNTIFS(NPI진행현황!$A$2:$A$300,$A8,NPI진행현황!$J$2:$J$300,"진행중")+COUNTIFS(NPI진행현황!$A$2:$A$300,$A8,NPI진행현황!$J$2:$J$300,"지연"))
A9: =IF(상품마스터!A9="","",상품마스터!A9) | B9: =IF($A9="","",상품마스터!B9) | C9: =IF($A9="","",상품마스터!D9) | D9: =IF($A9="","",COUNTIFS(NPI진행현황!$A$2:$A$300,$A9)) | E9: =IF($A9="","",IFERROR(AVERAGEIFS(NPI진행현황!$G$2:$G$300,NPI진행현황!$A$2:$A$300,$A9),"-")) | F9: =IF($A9="","",IFERROR(AVERAGEIFS(NPI진행현황!$G$2:$G$300,NPI진행현황!$A$2:$A$300,$A9,NPI진행현황!$B$2:$B$300,"CV-*"),"-")) | G9: =IF($A9="","",IFERROR(AVERAGEIFS(NPI진행현황!$G$2:$G$300,NPI진행현황!$A$2:$A$300,$A9,NPI진행현황!$B$2:$B$300,"CT-*"),"-")) | H9: =IF($A9="","",IFERROR(AVERAGEIFS(NPI진행현황!$G$2:$G$300,NPI진행현황!$A$2:$A$300,$A9,NPI진행현황!$B$2:$B$300,"PK-*"),"-")) | I9: =IF($A9="","",IFERROR(AVERAGEIFS(NPI진행현황!$G$2:$G$300,NPI진행현황!$A$2:$A$300,$A9,NPI진행현황!$B$2:$B$300,"SW-*"),"-")) | J9: =IF($A9="","",COUNTIFS(NPI진행현황!$A$2:$A$300,$A9,NPI진행현황!$F$2:$F$300,"기획")) | K9: =IF($A9="","",COUNTIFS(NPI진행현황!$A$2:$A$300,$A9,NPI진행현황!$F$2:$F$300,"EVT")) | L9: =IF($A9="","",COUNTIFS(NPI진행현황!$A$2:$A$300,$A9,NPI진행현황!$F$2:$F$300,"DVT")) | M9: =IF($A9="","",COUNTIFS(NPI진행현황!$A$2:$A$300,$A9,NPI진행현황!$F$2:$F$300,"PVT")) | N9: =IF($A9="","",COUNTIFS(NPI진행현황!$A$2:$A$300,$A9,NPI진행현황!$F$2:$F$300,"MP(양산)")) | O9: =IF($A9="","",COUNTIFS(NPI진행현황!$A$2:$A$300,$A9,NPI진행현황!$J$2:$J$300,"진행중")+COUNTIFS(NPI진행현황!$A$2:$A$300,$A9,NPI진행현황!$J$2:$J$300,"지연"))
A10: =IF(상품마스터!A10="","",상품마스터!A10) | B10: =IF($A10="","",상품마스터!B10) | C10: =IF($A10="","",상품마스터!D10) | D10: =IF($A10="","",COUNTIFS(NPI진행현황!$A$2:$A$300,$A10)) | E10: =IF($A10="","",IFERROR(AVERAGEIFS(NPI진행현황!$G$2:$G$300,NPI진행현황!$A$2:$A$300,$A10),"-")) | F10: =IF($A10="","",IFERROR(AVERAGEIFS(NPI진행현황!$G$2:$G$300,NPI진행현황!$A$2:$A$300,$A10,NPI진행현황!$B$2:$B$300,"CV-*"),"-")) | G10: =IF($A10="","",IFERROR(AVERAGEIFS(NPI진행현황!$G$2:$G$300,NPI진행현황!$A$2:$A$300,$A10,NPI진행현황!$B$2:$B$300,"CT-*"),"-")) | H10: =IF($A10="","",IFERROR(AVERAGEIFS(NPI진행현황!$G$2:$G$300,NPI진행현황!$A$2:$A$300,$A10,NPI진행현황!$B$2:$B$300,"PK-*"),"-")) | I10: =IF($A10="","",IFERROR(AVERAGEIFS(NPI진행현황!$G$2:$G$300,NPI진행현황!$A$2:$A$300,$A10,NPI진행현황!$B$2:$B$300,"SW-*"),"-")) | J10: =IF($A10="","",COUNTIFS(NPI진행현황!$A$2:$A$300,$A10,NPI진행현황!$F$2:$F$300,"기획")) | K10: =IF($A10="","",COUNTIFS(NPI진행현황!$A$2:$A$300,$A10,NPI진행현황!$F$2:$F$300,"EVT")) | L10: =IF($A10="","",COUNTIFS(NPI진행현황!$A$2:$A$300,$A10,NPI진행현황!$F$2:$F$300,"DVT")) | M10: =IF($A10="","",COUNTIFS(NPI진행현황!$A$2:$A$300,$A10,NPI진행현황!$F$2:$F$300,"PVT")) | N10: =IF($A10="","",COUNTIFS(NPI진행현황!$A$2:$A$300,$A10,NPI진행현황!$F$2:$F$300,"MP(양산)")) | O10: =IF($A10="","",COUNTIFS(NPI진행현황!$A$2:$A$300,$A10,NPI진행현황!$J$2:$J$300,"진행중")+COUNTIFS(NPI진행현황!$A$2:$A$300,$A10,NPI진행현황!$J$2:$J$300,"지연"))
A11: =IF(상품마스터!A11="","",상품마스터!A11) | B11: =IF($A11="","",상품마스터!B11) | C11: =IF($A11="","",상품마스터!D11) | D11: =IF($A11="","",COUNTIFS(NPI진행현황!$A$2:$A$300,$A11)) | E11: =IF($A11="","",IFERROR(AVERAGEIFS(NPI진행현황!$G$2:$G$300,NPI진행현황!$A$2:$A$300,$A11),"-")) | F11: =IF($A11="","",IFERROR(AVERAGEIFS(NPI진행현황!$G$2:$G$300,NPI진행현황!$A$2:$A$300,$A11,NPI진행현황!$B$2:$B$300,"CV-*"),"-")) | G11: =IF($A11="","",IFERROR(AVERAGEIFS(NPI진행현황!$G$2:$G$300,NPI진행현황!$A$2:$A$300,$A11,NPI진행현황!$B$2:$B$300,"CT-*"),"-")) | H11: =IF($A11="","",IFERROR(AVERAGEIFS(NPI진행현황!$G$2:$G$300,NPI진행현황!$A$2:$A$300,$A11,NPI진행현황!$B$2:$B$300,"PK-*"),"-")) | I11: =IF($A11="","",IFERROR(AVERAGEIFS(NPI진행현황!$G$2:$G$300,NPI진행현황!$A$2:$A$300,$A11,NPI진행현황!$B$2:$B$300,"SW-*"),"-")) | J11: =IF($A11="","",COUNTIFS(NPI진행현황!$A$2:$A$300,$A11,NPI진행현황!$F$2:$F$300,"기획")) | K11: =IF($A11="","",COUNTIFS(NPI진행현황!$A$2:$A$300,$A11,NPI진행현황!$F$2:$F$300,"EVT")) | L11: =IF($A11="","",COUNTIFS(NPI진행현황!$A$2:$A$300,$A11,NPI진행현황!$F$2:$F$300,"DVT")) | M11: =IF($A11="","",COUNTIFS(NPI진행현황!$A$2:$A$300,$A11,NPI진행현황!$F$2:$F$300,"PVT")) | N11: =IF($A11="","",COUNTIFS(NPI진행현황!$A$2:$A$300,$A11,NPI진행현황!$F$2:$F$300,"MP(양산)")) | O11: =IF($A11="","",COUNTIFS(NPI진행현황!$A$2:$A$300,$A11,NPI진행현황!$J$2:$J$300,"진행중")+COUNTIFS(NPI진행현황!$A$2:$A$300,$A11,NPI진행현황!$J$2:$J$300,"지연"))
A12: =IF(상품마스터!A12="","",상품마스터!A12) | B12: =IF($A12="","",상품마스터!B12) | C12: =IF($A12="","",상품마스터!D12) | D12: =IF($A12="","",COUNTIFS(NPI진행현황!$A$2:$A$300,$A12)) | E12: =IF($A12="","",IFERROR(AVERAGEIFS(NPI진행현황!$G$2:$G$300,NPI진행현황!$A$2:$A$300,$A12),"-")) | F12: =IF($A12="","",IFERROR(AVERAGEIFS(NPI진행현황!$G$2:$G$300,NPI진행현황!$A$2:$A$300,$A12,NPI진행현황!$B$2:$B$300,"CV-*"),"-")) | G12: =IF($A12="","",IFERROR(AVERAGEIFS(NPI진행현황!$G$2:$G$300,NPI진행현황!$A$2:$A$300,$A12,NPI진행현황!$B$2:$B$300,"CT-*"),"-")) | H12: =IF($A12="","",IFERROR(AVERAGEIFS(NPI진행현황!$G$2:$G$300,NPI진행현황!$A$2:$A$300,$A12,NPI진행현황!$B$2:$B$300,"PK-*"),"-")) | I12: =IF($A12="","",IFERROR(AVERAGEIFS(NPI진행현황!$G$2:$G$300,NPI진행현황!$A$2:$A$300,$A12,NPI진행현황!$B$2:$B$300,"SW-*"),"-")) | J12: =IF($A12="","",COUNTIFS(NPI진행현황!$A$2:$A$300,$A12,NPI진행현황!$F$2:$F$300,"기획")) | K12: =IF($A12="","",COUNTIFS(NPI진행현황!$A$2:$A$300,$A12,NPI진행현황!$F$2:$F$300,"EVT")) | L12: =IF($A12="","",COUNTIFS(NPI진행현황!$A$2:$A$300,$A12,NPI진행현황!$F$2:$F$300,"DVT")) | M12: =IF($A12="","",COUNTIFS(NPI진행현황!$A$2:$A$300,$A12,NPI진행현황!$F$2:$F$300,"PVT")) | N12: =IF($A12="","",COUNTIFS(NPI진행현황!$A$2:$A$300,$A12,NPI진행현황!$F$2:$F$300,"MP(양산)")) | O12: =IF($A12="","",COUNTIFS(NPI진행현황!$A$2:$A$300,$A12,NPI진행현황!$J$2:$J$300,"진행중")+COUNTIFS(NPI진행현황!$A$2:$A$300,$A12,NPI진행현황!$J$2:$J$300,"지연"))
A13: =IF(상품마스터!A13="","",상품마스터!A13) | B13: =IF($A13="","",상품마스터!B13) | C13: =IF($A13="","",상품마스터!D13) | D13: =IF($A13="","",COUNTIFS(NPI진행현황!$A$2:$A$300,$A13)) | E13: =IF($A13="","",IFERROR(AVERAGEIFS(NPI진행현황!$G$2:$G$300,NPI진행현황!$A$2:$A$300,$A13),"-")) | F13: =IF($A13="","",IFERROR(AVERAGEIFS(NPI진행현황!$G$2:$G$300,NPI진행현황!$A$2:$A$300,$A13,NPI진행현황!$B$2:$B$300,"CV-*"),"-")) | G13: =IF($A13="","",IFERROR(AVERAGEIFS(NPI진행현황!$G$2:$G$300,NPI진행현황!$A$2:$A$300,$A13,NPI진행현황!$B$2:$B$300,"CT-*"),"-")) | H13: =IF($A13="","",IFERROR(AVERAGEIFS(NPI진행현황!$G$2:$G$300,NPI진행현황!$A$2:$A$300,$A13,NPI진행현황!$B$2:$B$300,"PK-*"),"-")) | I13: =IF($A13="","",IFERROR(AVERAGEIFS(NPI진행현황!$G$2:$G$300,NPI진행현황!$A$2:$A$300,$A13,NPI진행현황!$B$2:$B$300,"SW-*"),"-")) | J13: =IF($A13="","",COUNTIFS(NPI진행현황!$A$2:$A$300,$A13,NPI진행현황!$F$2:$F$300,"기획")) | K13: =IF($A13="","",COUNTIFS(NPI진행현황!$A$2:$A$300,$A13,NPI진행현황!$F$2:$F$300,"EVT")) | L13: =IF($A13="","",COUNTIFS(NPI진행현황!$A$2:$A$300,$A13,NPI진행현황!$F$2:$F$300,"DVT")) | M13: =IF($A13="","",COUNTIFS(NPI진행현황!$A$2:$A$300,$A13,NPI진행현황!$F$2:$F$300,"PVT")) | N13: =IF($A13="","",COUNTIFS(NPI진행현황!$A$2:$A$300,$A13,NPI진행현황!$F$2:$F$300,"MP(양산)")) | O13: =IF($A13="","",COUNTIFS(NPI진행현황!$A$2:$A$300,$A13,NPI진행현황!$J$2:$J$300,"진행중")+COUNTIFS(NPI진행현황!$A$2:$A$300,$A13,NPI진행현황!$J$2:$J$300,"지연"))
... A51: =IF(상품마스터!A51="","",상품마스터!A51) | B51: =IF($A51="","",상품마스터!B51) | C51: =IF($A51="","",상품마스터!D51) | D51: =IF($A51="","",COUNTIFS(NPI진행현황!$A$2:$A$300,$A51)) | E51: =IF($A51="","",IFERROR(AVERAGEIFS(NPI진행현황!$G$2:$G$300,NPI진행현황!$A$2:$A$300,$A51),"-")) | F51: =IF($A51="","",IFERROR(AVERAGEIFS(NPI진행현황!$G$2:$G$300,NPI진행현황!$A$2:$A$300,$A51,NPI진행현황!$B$2:$B$300,"CV-*"),"-")) | G51: =IF($A51="","",IFERROR(AVERAGEIFS(NPI진행현황!$G$2:$G$300,NPI진행현황!$A$2:$A$300,$A51,NPI진행현황!$B$2:$B$300,"CT-*"),"-")) | H51: =IF($A51="","",IFERROR(AVERAGEIFS(NPI진행현황!$G$2:$G$300,NPI진행현황!$A$2:$A$300,$A51,NPI진행현황!$B$2:$B$300,"PK-*"),"-")) | I51: =IF($A51="","",IFERROR(AVERAGEIFS(NPI진행현황!$G$2:$G$300,NPI진행현황!$A$2:$A$300,$A51,NPI진행현황!$B$2:$B$300,"SW-*"),"-")) | J51: =IF($A51="","",COUNTIFS(NPI진행현황!$A$2:$A$300,$A51,NPI진행현황!$F$2:$F$300,"기획")) | K51: =IF($A51="","",COUNTIFS(NPI진행현황!$A$2:$A$300,$A51,NPI진행현황!$F$2:$F$300,"EVT")) | L51: =IF($A51="","",COUNTIFS(NPI진행현황!$A$2:$A$300,$A51,NPI진행현황!$F$2:$F$300,"DVT")) | M51: =IF($A51="","",COUNTIFS(NPI진행현황!$A$2:$A$300,$A51,NPI진행현황!$F$2:$F$300,"PVT")) | N51: =IF($A51="","",COUNTIFS(NPI진행현황!$A$2:$A$300,$A51,NPI진행현황!$F$2:$F$300,"MP(양산)")) | O51: =IF($A51="","",COUNTIFS(NPI진행현황!$A$2:$A$300,$A51,NPI진행현황!$J$2:$J$300,"진행중")+COUNTIFS(NPI진행현황!$A$2:$A$300,$A51,NPI진행현황!$J$2:$J$300,"지연"))
A53: ※ 이 시트는 전부 수식입니다. 상품마스터 · NPI진행현황에 입력하면 자동 집계됩니다. 완성률 = 해당 상품의 NPI 부품별 완료율 단순 평균(가중치 없음). 대분류별은 품번 접두어(CV/CT/PK/SW) 기준.

Sheet ECN변경이력
A1: ECN번호 | B1: 일자 | C1: 품번 | D1: 품명 | E1: 변경구분 | F1: 리비전(전→후) | G1: 변경 전 | H1: 변경 후 | I1: 사유 | J1: 요청자ID | K1: 승인자ID | L1: 영향 상품 | M1: 상태 | N1: 비고
A2: ECN-2026-001 | B2: 2026-08-20 | C2: CT-001 | D2: =IF(C2="","",IFERROR(INDEX(품목마스터!$B$2:$B$300,MATCH(C2,품목마스터!$A$2:$A$300,0)),"※미등록")) -> 컨트롤러 아세이 (윈도우커버라벨 포함) | E2: 사양변경 | F2: A→B | G2: 윈도우커버라벨 인쇄 실크 | H2: 윈도우커버라벨 인쇄 UV | I2: 색상 불일치 개선 | J2: E-003 | K2: E-001 | L2: MAT-001 | M2: 승인 | N2: 예시 데이터
D3: =IF(C3="","",IFERROR(INDEX(품목마스터!$B$2:$B$300,MATCH(C3,품목마스터!$A$2:$A$300,0)),"※미등록"))
D4: =IF(C4="","",IFERROR(INDEX(품목마스터!$B$2:$B$300,MATCH(C4,품목마스터!$A$2:$A$300,0)),"※미등록"))
D5: =IF(C5="","",IFERROR(INDEX(품목마스터!$B$2:$B$300,MATCH(C5,품목마스터!$A$2:$A$300,0)),"※미등록"))
D6: =IF(C6="","",IFERROR(INDEX(품목마스터!$B$2:$B$300,MATCH(C6,품목마스터!$A$2:$A$300,0)),"※미등록"))
D7: =IF(C7="","",IFERROR(INDEX(품목마스터!$B$2:$B$300,MATCH(C7,품목마스터!$A$2:$A$300,0)),"※미등록"))
D8: =IF(C8="","",IFERROR(INDEX(품목마스터!$B$2:$B$300,MATCH(C8,품목마스터!$A$2:$A$300,0)),"※미등록"))
D9: =IF(C9="","",IFERROR(INDEX(품목마스터!$B$2:$B$300,MATCH(C9,품목마스터!$A$2:$A$300,0)),"※미등록"))
D10: =IF(C10="","",IFERROR(INDEX(품목마스터!$B$2:$B$300,MATCH(C10,품목마스터!$A$2:$A$300,0)),"※미등록"))
D11: =IF(C11="","",IFERROR(INDEX(품목마스터!$B$2:$B$300,MATCH(C11,품목마스터!$A$2:$A$300,0)),"※미등록"))
D12: =IF(C12="","",IFERROR(INDEX(품목마스터!$B$2:$B$300,MATCH(C12,품목마스터!$A$2:$A$300,0)),"※미등록"))
D13: =IF(C13="","",IFERROR(INDEX(품목마스터!$B$2:$B$300,MATCH(C13,품목마스터!$A$2:$A$300,0)),"※미등록"))
D14: =IF(C14="","",IFERROR(INDEX(품목마스터!$B$2:$B$300,MATCH(C14,품목마스터!$A$2:$A$300,0)),"※미등록"))
... D300: =IF(C300="","",IFERROR(INDEX(품목마스터!$B$2:$B$300,MATCH(C300,품목마스터!$A$2:$A$300,0)),"※미등록"))

Sheet 코드표
A1: 대분류 | B1: 품목구분 | C1: 개발단계 | D1: 승인상태 | E1: 상품상태 | F1: 이슈상태 | G1: 협력사유형 | H1: 변경구분 | I1: 필수여부
A2: 커버 | B2: 어셈블리 | C2: 기획 | D2: 후보 | E2: 기획 | F2: 없음 | G2: 제조 | H2: 사양변경 | I2: 필수
A3: 컨트롤러 | B3: 부품 | C3: EVT | D3: 샘플평가 | E3: 개발 | F3: 진행중 | G3: OEM/ODM | H3: 제조사변경 | I3: 옵션
A4: 포장 | B4: 포장재 | C4: DVT | D4: 승인 | E4: 양산 | F4: 지연 | G4: 소프트웨어 | H4: 도면변경
A5: APP | B5: 포장사양 | C5: PVT | D5: 보류 | E5: 단종 | F5: 해결 | G5: 인쇄 | H5: SW버전
B6: 문서 | C6: MP(양산) | D6: 탈락 | G6: 물류 | H6: 포장변경
B7: 소프트웨어 | C7: 단종 | G7: 기타 | H7: 기타
